<?xml version="1.0" ?>
<!-- =================================================================================== -->
<!-- |    This document was autogenerated by xacro from boris.urdf.xacro               | -->
<!-- |    EDITING THIS FILE BY HAND IS NOT RECOMMENDED                                 | -->
<!-- =================================================================================== -->
<robot name="boris" xmlns:xacro="http://www.ros.org/wiki/xacro">
  <material name="Boris/DarkGrey">
    <color rgba="0.3 0.3 0.3 1.0"/>
  </material>
  <material name="Boris/LightGrey">
    <color rgba="0.8 0.8 0.8 1.0"/>
  </material>
  <material name="Boris/Red">
    <color rgba="0.3 0.3 0.3 1.0"/>
  </material>
  <material name="Boris/Black">
    <color rgba="0 0 0 1.0"/>
  </material>
  <material name="Boris/Orange">
    <!-- <color rgba="1.0 0.487 0 1.0"/> -->
    <color rgba="0.0 0.0 0.8 1.0"/>
  </material>
  <material name="Boris/Silver">
    <color rgba="1.0 1.0 1.0 1.0"/>
  </material>
  <material name="Boris/Grey">
    <color rgba="0.7 0.7 0.7 1.0"/>
  </material>
  <material name="Boris/Blue">
    <color rgba="0.0 0.0 0.8 1.0"/>
  </material>
  <material name="Boris/HandGray">
    <color rgba="0.953 0.996 0.694 1.0"/>
  </material>
  <material name="Boris/SickBlue">
    <color rgba="0.3058 0.5921 0.7294 1.0"/>
  </material>
  <material name="Kuka/DarkGrey">
    <color rgba="0.3 0.3 0.3 1.0"/>
  </material>
  <material name="Kuka/LightGrey">
    <color rgba="0.8 0.8 0.8 1.0"/>
  </material>
  <material name="Kuka/Red">
    <color rgba="0.3 0.3 0.3 1.0"/>
  </material>
  <material name="Kuka/Black">
    <color rgba="0 0 0 1.0"/>
  </material>
  <material name="Kuka/Orange">
    <color rgba="1.0 0.487 0 1.0"/>
  </material>
  <material name="Kuka/Silver">
    <color rgba="1.0 1.0 1.0 1.0"/>
  </material>
  <material name="Kuka/Grey">
    <color rgba="0.7 0.7 0.7 1.0"/>
  </material>
  <material name="Kuka/Blue">
    <color rgba="0.0 0.0 0.8 1.0"/>
  </material>
  <!-- reflex to stiffness -->
  <material name="SoftHand/LightGrey">
    <color rgba="0.7 0.7 0.7 1.0"/>
  </material>
  <material name="SoftHand/DarkGrey">
    <color rgba="0.4 0.4 0.4 1.0"/>
  </material>
  <material name="SoftHand/Black">
    <color rgba="0.0 0.0 0.0 1.0"/>
  </material>
  <material name="SoftHand/DarkGolden">
    <color rgba="0.4 0.4 0.3 1.0"/>
  </material>
  <material name="SoftHand/Blue">
    <color rgba="0.0 0.0 0.8 0.9"/>
  </material>
  <material name="SoftHand/LightBlue">
    <color rgba="0.0 0.4 1.0 0.5"/>
  </material>
  <!-- <xacro:insert_block name="gazebo_friction_properties"/> -->
  <!-- <xacro:insert_block name="gazebo_other_properties"/> -->
  <!-- NOTE: inertia values are approximated using meshlab and only using the significant elements -->
  <!-- from http://answers.ros.org/question/11350/is-there-any-way-to-calculate-inertial-property-of-a-robot-to-simulate-it-in-gazebo/s
    One general rule of thumb I use for checking my inertia tensors is: If total mass of the rigid body is m, and the dimension of the corresponding body is d, then check to see if ixx, iyy, izz are near m*(d/2)^2.

    This is by no means correct, but a sanity check to make sure the moment of inertia are the right order of magnitudes, so the model behaves somewhat physically realistically.
    -->
  <material name="KIT/White">
    <color rgba="1 1 1 1.0"/>
  </material>
  <material name="KIT/DarkGrey">
    <color rgba="0.3 0.3 0.3 1.0"/>
  </material>
  <material name="KIT/LightGrey">
    <color rgba="0.8 0.8 0.8 1.0"/>
  </material>
  <material name="KIT/Red">
    <color rgba="0.3 0.3 0.3 1.0"/>
  </material>
  <material name="KIT/Black">
    <color rgba="0 0 0 1.0"/>
  </material>
  <material name="KIT/Orange">
    <color rgba="1.0 0.487 0 1.0"/>
  </material>
  <material name="KIT/Silver">
    <color rgba="1.0 1.0 1.0 1.0"/>
  </material>
  <material name="KIT/Grey">
    <color rgba="0.7 0.7 0.7 1.0"/>
  </material>
  <material name="KIT/Blue">
    <color rgba="0.0 0.0 0.8 1.0"/>
  </material>
  <material name="KIT/HandGray">
    <color rgba="0.953 0.996 0.694 1.0"/>
  </material>
  <material name="KIT/SickBlue">
    <color rgba="0.3058 0.5921 0.7294 1.0"/>
  </material>
  <!-- NOTE: inertia values are approximated using meshlab and only using the significant elements -->
  <!-- from http://answers.ros.org/question/11350/is-there-any-way-to-calculate-inertial-property-of-a-robot-to-simulate-it-in-gazebo/s
    One general rule of thumb I use for checking my inertia tensors is: If total mass of the rigid body is m, and the dimension of the corresponding body is d, then check to see if ixx, iyy, izz are near m*(d/2)^2.

    This is by no means correct, but a sanity check to make sure the moment of inertia are the right order of magnitudes, so the model behaves somewhat physically realistically.
    -->
  <!-- real inertia for the head are still required -->
  <link name="world"/>
  <joint name="world_table_base_joint" type="fixed">
    <origin rpy="0 0 0" xyz="-0.075 0.075 0"/>
    <parent link="world"/>
    <child link="table_plate_link"/>
  </joint>
  <link name="table_plate_link">
    <inertial>
      <origin xyz="0 0 0"/>
      <mass value="500.0"/>
      <inertia ixx="5.0" ixy="0.0" ixz="0.0" iyy="5.0" iyz="0.0" izz="5.0"/>
    </inertial>
    <visual>
      <origin xyz="0.075 -0.075 -0.025"/>
      <geometry>
        <box size="0.15 0.15 0.05"/>
      </geometry>
      <material name="Boris/LightGrey"/>
    </visual>
    <collision>
      <origin xyz="0.075 -0.075 -0.025"/>
      <geometry>
        <box size="0.15 0.15 0.05"/>
      </geometry>
    </collision>
  </link>
  <joint name="table_leg_0_joint" type="fixed">
    <origin xyz="0.055 -0.055 -0.48"/>
    <parent link="table_plate_link"/>
    <child link="table_leg_0_link"/>
  </joint>
  <link name="table_leg_0_link">
    <inertial>
      <origin xyz="0 0 0"/>
      <mass value="500.0"/>
      <inertia ixx="5.0" ixy="0.0" ixz="0.0" iyy="5.0" iyz="0.0" izz="5.0"/>
    </inertial>
    <visual>
      <geometry>
        <box size="0.04 -0.08 0.86"/>
      </geometry>
      <material name="Boris/Black"/>
    </visual>
    <collision>
      <geometry>
        <box size="0.04 -0.08 0.86"/>
      </geometry>
    </collision>
  </link>
  <gazebo reference="table_leg_0_link">
    <static>true</static>
  </gazebo>
  <joint name="table_leg_1_joint" type="fixed">
    <origin xyz="0.095 -0.055 -0.48"/>
    <parent link="table_plate_link"/>
    <child link="table_leg_1_link"/>
  </joint>
  <link name="table_leg_1_link">
    <inertial>
      <origin xyz="0 0 0"/>
      <mass value="500.0"/>
      <inertia ixx="5.0" ixy="0.0" ixz="0.0" iyy="5.0" iyz="0.0" izz="5.0"/>
    </inertial>
    <visual>
      <geometry>
        <box size="0.04 -0.08 0.86"/>
      </geometry>
      <material name="Boris/Black"/>
    </visual>
    <collision>
      <geometry>
        <box size="0.04 -0.08 0.86"/>
      </geometry>
    </collision>
  </link>
  <gazebo reference="table_leg_1_link">
    <static>true</static>
  </gazebo>
  <joint name="table_leg_2_joint" type="fixed">
    <origin xyz="0.055 -0.095 -0.48"/>
    <parent link="table_plate_link"/>
    <child link="table_leg_2_link"/>
  </joint>
  <link name="table_leg_2_link">
    <inertial>
      <origin xyz="0 0 0"/>
      <mass value="500.0"/>
      <inertia ixx="5.0" ixy="0.0" ixz="0.0" iyy="5.0" iyz="0.0" izz="5.0"/>
    </inertial>
    <visual>
      <geometry>
        <box size="0.04 -0.08 0.86"/>
      </geometry>
      <material name="Boris/Black"/>
    </visual>
    <collision>
      <geometry>
        <box size="0.04 -0.08 0.86"/>
      </geometry>
    </collision>
  </link>
  <gazebo reference="table_leg_2_link">
    <static>true</static>
  </gazebo>
  <joint name="table_leg_3_joint" type="fixed">
    <origin xyz="0.095 -0.095 -0.48"/>
    <parent link="table_plate_link"/>
    <child link="table_leg_3_link"/>
  </joint>
  <link name="table_leg_3_link">
    <inertial>
      <origin xyz="0 0 0"/>
      <mass value="500.0"/>
      <inertia ixx="5.0" ixy="0.0" ixz="0.0" iyy="5.0" iyz="0.0" izz="5.0"/>
    </inertial>
    <visual>
      <geometry>
        <box size="0.04 -0.08 0.86"/>
      </geometry>
      <material name="Boris/Black"/>
    </visual>
    <collision>
      <geometry>
        <box size="0.04 -0.08 0.86"/>
      </geometry>
    </collision>
  </link>
  <gazebo reference="table_leg_3_link">
    <static>true</static>
  </gazebo>
  <gazebo reference="table_plate_link">
    <static>true</static>
  </gazebo>
  <joint name="wall_joint" type="fixed">
    <origin rpy="0 0 0" xyz="-0.40 0 0"/>
    <parent link="world"/>
    <child link="wall_link"/>
  </joint>
  <link name="wall_link">
    <inertial>
      <origin xyz="0 0 0"/>
      <mass value="10"/>
      <inertia ixx="6.66666666667" ixy="0" ixz="0" iyy="3.54166666667" iyz="0" izz="3.54166666667"/>
    </inertial>
    <visual>
      <origin rpy="0 0 0" xyz="0.0 0 0"/>
      <geometry>
        <box size="0.25 2.0 2.0"/>
      </geometry>
      <material name="Boris/LightGrey"/>
    </visual>
    <collision>
      <origin rpy="0 0 0" xyz="0.0 0 0"/>
      <geometry>
        <box size="0.25 2.0 2.0"/>
      </geometry>
    </collision>
  </link>
  <gazebo reference="wall_link">
    <!-- <static>true</static> -->
  </gazebo>
  <joint name="world_torso_base_joint" type="fixed">
    <origin rpy="0 0 3.14159265359" xyz="0 0 0"/>
    <parent link="world"/>
    <child link="torso_link"/>
  </joint>
  <link name="torso_link">
    <inertial>
      <origin xyz="0 0 0"/>
      <mass value="20.0"/>
      <inertia ixx="0.2" ixy="0.0" ixz="0.0" iyy="0.2" iyz="0.0" izz="0.2"/>
    </inertial>
    <visual>
      <geometry>
        <mesh filename="package://boris_description/meshes/torso.stl"/>
      </geometry>
      <material name="Boris/Silver"/>
    </visual>
    <collision>
      <geometry>
        <mesh filename="package://boris_description/meshes/torso.stl"/>
      </geometry>
    </collision>
  </link>
  <gazebo reference="torso_link">
    <!-- <static>true</static> -->
  </gazebo>
  <!-- <link name="${base_link}"/> -->
  <!-- <gazebo reference="${base_link}">
      <static>true</static>
      <turnGravityOff>true</turnGravityOff>
    </gazebo> -->
  <!-- First (shoulder) element of the arm. Fixed to its parent. -->
  <joint name="left_arm_base_joint" type="fixed">
    <origin rpy="0 -1.308996939 -1.57079632679" xyz="0 0.12853 0.20722"/>
    <origin rpy="0 0 0" xyz="0 0 0"/>
    <parent link="world"/>
    <child link="left_arm_base_link"/>
  </joint>
  <link name="left_arm_base_link">
    <inertial>
      <mass value="2.0"/>
      <origin xyz="0 0 0.055"/>
      <inertia ixx="0.00381666666667" ixy="0" ixz="0" iyy="0.0036" iyz="0" izz="0.00381666666667"/>
    </inertial>
    <visual>
      <origin rpy="0 0 3.14159265359" xyz="0 0 0"/>
      <geometry>
        <mesh filename="package://lwr_description/meshes_arm/arm_base.dae"/>
      </geometry>
      <material name="Kuka/Orange"/>
    </visual>
    <collision>
      <origin rpy="0 0 3.14159265359" xyz="0 0 0.055"/>
      <geometry>
        <!-- <mesh filename="package://lwr_description/meshes/convex/arm_base_convex.stl"/> -->
        <cylinder length="0.11" radius="0.07"/>
      </geometry>
    </collision>
  </link>
  <!-- Second segment of the arm. Joint along z-axis -->
  <joint name="left_arm_0_joint" type="revolute">
    <origin rpy="0 0 0" xyz="0 0 0.11"/>
    <axis xyz="0 0 1"/>
    <limit effort="176" lower="-2.96705972839" upper="2.96705972839" velocity="1.91986217719"/>
    <dynamics damping="1.0" friction="10.0"/>
    <parent link="left_arm_base_link"/>
    <child link="left_arm_1_link"/>
  </joint>
  <!-- 			LINK 1 			-->
  <link name="left_arm_1_link">
    <inertial>
      <mass value="2.0"/>
      <origin rpy="0 0 0" xyz="0 -0.06 0.130"/>
      <inertia ixx="0.0136666666667" ixy="0" ixz="0" iyy="0.003" iyz="0" izz="0.0118666666667"/>
    </inertial>
    <visual>
      <origin rpy="0 0 3.14159265359" xyz="0 0 0"/>
      <geometry>
        <mesh filename="package://lwr_description/meshes_arm/arm_segment_a.dae"/>
      </geometry>
      <material name="Orange"/>
    </visual>
    <collision>
      <origin rpy="0 0 0" xyz="0 0 0.0"/>
      <geometry>
        <!--mesh filename="package://lwr_description/meshes/convex/arm_segment_a_convex.stl"/-->
        <sphere radius="0.07"/>
      </geometry>
    </collision>
    <collision>
      <origin rpy="0 0 0" xyz="0 0.06 0.2"/>
      <geometry>
        <sphere radius="0.07"/>
      </geometry>
    </collision>
    <collision>
      <origin rpy="-0.291 0 0" xyz="0 0.03 0.1"/>
      <geometry>
        <cylinder length="0.208" radius="0.07"/>
      </geometry>
    </collision>
  </link>
  <!-- Third segment of the arm. Joint along y-axis -->
  <joint name="left_arm_1_joint" type="revolute">
    <origin rpy="0 0 0" xyz="0 0 0.2005"/>
    <axis xyz="0 -1 0"/>
    <limit effort="176" lower="-2.09439510239" upper="2.09439510239" velocity="1.91986217719"/>
    <dynamics damping="1.0" friction="10.0"/>
    <parent link="left_arm_1_link"/>
    <child link="left_arm_2_link"/>
  </joint>
  <!-- 			LINK 2 			-->
  <link name="left_arm_2_link">
    <inertial>
      <mass value="2.0"/>
      <origin rpy="0 0 0" xyz="0 0.06 0.07"/>
      <inertia ixx="0.0136666666667" ixy="0" ixz="0" iyy="0.003" iyz="0" izz="0.0118666666667"/>
    </inertial>
    <visual>
      <origin rpy="3.14159265359 0 3.14159265359" xyz="0 0 0.2"/>
      <geometry>
        <mesh filename="package://lwr_description/meshes_arm/arm_segment_b.dae"/>
      </geometry>
      <material name="Orange"/>
    </visual>
    <collision>
      <origin rpy="0 0 0" xyz="0 0 0.2"/>
      <geometry>
        <!--mesh filename="package://lwr_description/meshes/convex/arm_segment_b_convex.stl"/-->
        <sphere radius="0.07"/>
      </geometry>
    </collision>
    <collision>
      <origin rpy="0 0 0" xyz="0 -0.06 0.0"/>
      <geometry>
        <sphere radius="0.07"/>
      </geometry>
    </collision>
    <collision>
      <origin rpy="-0.291 0 0" xyz="0 -0.03 0.1"/>
      <geometry>
        <cylinder length="0.208" radius="0.07"/>
      </geometry>
    </collision>
  </link>
  <!-- Fourth element of the arm. z-axis -->
  <joint name="left_arm_2_joint" type="revolute">
    <origin rpy="0 0 0" xyz="0 0 0.20"/>
    <axis xyz="0 0 1"/>
    <limit effort="100" lower="-2.96705972839" upper="2.96705972839" velocity="2.23402144255"/>
    <dynamics damping="1.0" friction="10.0"/>
    <parent link="left_arm_2_link"/>
    <child link="left_arm_3_link"/>
  </joint>
  <!-- 			LINK 3 			-->
  <link name="left_arm_3_link">
    <inertial>
      <mass value="2.0"/>
      <origin rpy="0 0 0" xyz="0 0.06 0.130"/>
      <inertia ixx="0.0136666666667" ixy="0" ixz="0" iyy="0.003" iyz="0" izz="0.0118666666667"/>
    </inertial>
    <visual>
      <origin rpy="0 0 0" xyz="0 0 0"/>
      <geometry>
        <mesh filename="package://lwr_description/meshes_arm/arm_segment_a.dae"/>
      </geometry>
      <material name="Orange"/>
    </visual>
    <collision>
      <origin rpy="0 0 0" xyz="0 0 0.0"/>
      <geometry>
        <!--mesh filename="package://lwr_description/meshes/convex/arm_segment_a_convex.stl"/-->
        <sphere radius="0.07"/>
      </geometry>
    </collision>
    <collision>
      <origin rpy="0 0 0" xyz="0 -0.06 0.2"/>
      <geometry>
        <sphere radius="0.07"/>
      </geometry>
    </collision>
    <collision>
      <origin rpy="0.291 0 0" xyz="0 -0.03 0.1"/>
      <geometry>
        <cylinder length="0.208" radius="0.07"/>
      </geometry>
    </collision>
  </link>
  <!-- fifth element of the arm. x-axis -->
  <joint name="left_arm_3_joint" type="revolute">
    <origin rpy="0 0 0" xyz="0 0 0.20"/>
    <axis xyz="0 1 0"/>
    <limit effort="100" lower="-2.09439510239" upper="2.09439510239" velocity="2.23402144255"/>
    <dynamics damping="1.0" friction="10.0"/>
    <parent link="left_arm_3_link"/>
    <child link="left_arm_4_link"/>
  </joint>
  <!-- 			LINK 4 			-->
  <link name="left_arm_4_link">
    <inertial>
      <mass value="2.0"/>
      <origin rpy="0 0 0" xyz="0 -0.06 0.07"/>
      <inertia ixx="0.0136666666667" ixy="0" ixz="0" iyy="0.003" iyz="0" izz="0.0118666666667"/>
    </inertial>
    <visual>
      <origin rpy="0 3.14159265359 3.14159265359" xyz="0 0 0.2"/>
      <geometry>
        <mesh filename="package://lwr_description/meshes_arm/arm_segment_b.dae"/>
      </geometry>
      <material name="Orange"/>
    </visual>
    <collision>
      <origin rpy="0 0 0" xyz="0 0 0.2"/>
      <geometry>
        <!--mesh filename="package://lwr_description/meshes/convex/arm_segment_b_convex.stl"/-->
        <sphere radius="0.07"/>
      </geometry>
    </collision>
    <collision>
      <origin rpy="0 0 0" xyz="0 0.06 0.0"/>
      <geometry>
        <sphere radius="0.07"/>
      </geometry>
    </collision>
    <collision>
      <origin rpy="0.291 0 0" xyz="0 0.03 0.1"/>
      <geometry>
        <cylinder length="0.208" radius="0.07"/>
      </geometry>
    </collision>
  </link>
  <!-- Sixth element of the arm. z-axis -->
  <joint name="left_arm_4_joint" type="revolute">
    <origin rpy="0 0 0" xyz="0 0 0.20"/>
    <axis xyz="0 0 1"/>
    <limit effort="100" lower="-2.96705972839" upper="2.96705972839" velocity="3.56047167407"/>
    <dynamics damping="1.0" friction="10.0"/>
    <parent link="left_arm_4_link"/>
    <child link="left_arm_5_link"/>
  </joint>
  <!-- 			LINK 5 			-->
  <link name="left_arm_5_link">
    <inertial>
      <mass value="2.0"/>
      <origin rpy="0 0 0" xyz="0 0 0.124"/>
      <inertia ixx="0.0126506666667" ixy="0" ixz="0" iyy="0.003" iyz="0" izz="0.0108506666667"/>
    </inertial>
    <visual>
      <origin rpy="0 0 3.14159265359" xyz="0 0 0"/>
      <geometry name="left_arm_arm_5_geom">
        <mesh filename="package://lwr_description/meshes_arm/arm_segment_last.dae"/>
      </geometry>
      <material name="Orange"/>
    </visual>
    <collision>
      <origin rpy="0 0 0" xyz="0 0 0.0"/>
      <geometry>
        <!--mesh filename="package://lwr_description/meshes/convex/arm_segment_last_convex.stl"/-->
        <sphere radius="0.07"/>
      </geometry>
    </collision>
    <collision>
      <origin rpy="0 0 0" xyz="0 0.04 0.19"/>
      <geometry>
        <sphere radius="0.07"/>
      </geometry>
    </collision>
    <collision>
      <origin rpy="-0.207 0 0" xyz="0 0.02 0.095"/>
      <geometry>
        <cylinder length="0.198" radius="0.07"/>
      </geometry>
    </collision>
  </link>
  <!-- Seventh element of the arm. z-axis -->
  <joint name="left_arm_5_joint" type="revolute">
    <origin rpy="0 0 0" xyz="0 0 0.19"/>
    <axis xyz="0 -1 0"/>
    <limit effort="38" lower="-2.09439510239" upper="2.09439510239" velocity="3.21140582367"/>
    <dynamics damping="1.0" friction="10.0"/>
    <parent link="left_arm_5_link"/>
    <child link="left_arm_6_link"/>
  </joint>
  <!-- 			LINK 6 			-->
  <link name="left_arm_6_link">
    <inertial>
      <mass value="0.2"/>
      <origin rpy="0 0 0" xyz="0 0 0.0625"/>
      <inertia ixx="0.000520833333333" ixy="0" ixz="0" iyy="0.000520833333333" iyz="0" izz="0.000520833333333"/>
    </inertial>
    <visual>
      <origin rpy="0 0 3.14159265359" xyz="0 0 0"/>
      <geometry>
        <mesh filename="package://lwr_description/meshes_arm/arm_wrist.dae"/>
      </geometry>
      <material name="Grey"/>
    </visual>
    <collision>
      <origin rpy="0 0 3.14159265359" xyz="0 0 0"/>
      <geometry>
        <mesh filename="package://lwr_description/meshes/convex/arm_wrist_convex.stl"/>
      </geometry>
    </collision>
  </link>
  <!-- Eighth element of the arm. z-axis -->
  <joint name="left_arm_6_joint" type="revolute">
    <origin rpy="0 0 0" xyz="0 0 0.078"/>
    <axis xyz="0 0 1"/>
    <limit effort="38" lower="-2.96705972839" upper="2.96705972839" velocity="3.21140582367"/>
    <dynamics damping="1.0" friction="10.0"/>
    <parent link="left_arm_6_link"/>
    <child link="left_arm_7_link"/>
  </joint>
  <!-- 			LINK 7 			-->
  <link name="left_arm_7_link">
    <inertial>
      <mass value="0.2"/>
      <origin xyz="0 0 0"/>
      <inertia ixx="0.0333333333333" ixy="0" ixz="0" iyy="0.0333333333333" iyz="0" izz="0.0333333333333"/>
    </inertial>
    <visual>
      <origin rpy="0 0 3.14159265359" xyz="0 0 0"/>
      <geometry>
        <mesh filename="package://lwr_description/meshes/link_7.dae"/>
      </geometry>
      <material name="Kuka/DarkGrey"/>
    </visual>
    <collision>
      <origin rpy="0 0 3.14159265359" xyz="0 0 0"/>
      <geometry>
        <cylinder length="0.05" radius="0.04"/>
      </geometry>
    </collision>
  </link>
  <gazebo>
    <plugin filename="liblwr_hw_gazebo_plugin.so" name="left_arm_lwr_hw_sim">
      <robotNamespace>left_arm</robotNamespace>
    </plugin>
  </gazebo>
  <!--gazebo>
  	<plugin name="gazebo_ros_control" filename="libgazebo_ros_control.so">
   	<robotNamespace>${name}</robotNamespace>
 	</plugin>
	</gazebo-->
  <gazebo reference="left_arm_base_link">
    <gravity>true</gravity>
  </gazebo>
  <gazebo reference="left_arm_1_link">
    <gravity>true</gravity>
  </gazebo>
  <gazebo reference="left_arm_2_link">
    <gravity>true</gravity>
  </gazebo>
  <gazebo reference="left_arm_3_link">
    <gravity>true</gravity>
  </gazebo>
  <gazebo reference="left_arm_4_link">
    <gravity>true</gravity>
  </gazebo>
  <gazebo reference="left_arm_5_link">
    <gravity>true</gravity>
  </gazebo>
  <gazebo reference="left_arm_6_link">
    <gravity>true</gravity>
  </gazebo>
  <gazebo reference="left_arm_7_link">
    <gravity>true</gravity>
  </gazebo>
  <transmission name="left_arm_0_trans">
    <type>transmission_interface/SimpleTransmission</type>
    <joint name="left_arm_0_joint">
      <hardwareInterface>hardware_interface/EffortJointInterface</hardwareInterface>
      <hardwareInterface>hardware_interface/PositionJointInterface</hardwareInterface>
    </joint>
    <actuator name="left_arm_0_motor">
      <mechanicalReduction>1</mechanicalReduction>
    </actuator>
  </transmission>
  <transmission name="left_arm_1_trans">
    <type>transmission_interface/SimpleTransmission</type>
    <joint name="left_arm_1_joint">
      <hardwareInterface>hardware_interface/EffortJointInterface</hardwareInterface>
      <hardwareInterface>hardware_interface/PositionJointInterface</hardwareInterface>
    </joint>
    <actuator name="left_arm_1_motor">
      <mechanicalReduction>1</mechanicalReduction>
    </actuator>
  </transmission>
  <transmission name="left_arm_2_trans">
    <type>transmission_interface/SimpleTransmission</type>
    <joint name="left_arm_2_joint">
      <hardwareInterface>hardware_interface/EffortJointInterface</hardwareInterface>
      <hardwareInterface>hardware_interface/PositionJointInterface</hardwareInterface>
    </joint>
    <actuator name="left_arm_2_motor">
      <mechanicalReduction>1</mechanicalReduction>
    </actuator>
  </transmission>
  <transmission name="left_arm_3_trans">
    <type>transmission_interface/SimpleTransmission</type>
    <joint name="left_arm_3_joint">
      <hardwareInterface>hardware_interface/EffortJointInterface</hardwareInterface>
      <hardwareInterface>hardware_interface/PositionJointInterface</hardwareInterface>
    </joint>
    <actuator name="left_arm_3_motor">
      <mechanicalReduction>1</mechanicalReduction>
    </actuator>
  </transmission>
  <transmission name="left_arm_4_trans">
    <type>transmission_interface/SimpleTransmission</type>
    <joint name="left_arm_4_joint">
      <hardwareInterface>hardware_interface/EffortJointInterface</hardwareInterface>
      <hardwareInterface>hardware_interface/PositionJointInterface</hardwareInterface>
    </joint>
    <actuator name="left_arm_4_motor">
      <mechanicalReduction>1</mechanicalReduction>
    </actuator>
  </transmission>
  <transmission name="left_arm_5_trans">
    <type>transmission_interface/SimpleTransmission</type>
    <joint name="left_arm_5_joint">
      <hardwareInterface>hardware_interface/EffortJointInterface</hardwareInterface>
      <hardwareInterface>hardware_interface/PositionJointInterface</hardwareInterface>
    </joint>
    <actuator name="left_arm_5_motor">
      <mechanicalReduction>1</mechanicalReduction>
    </actuator>
  </transmission>
  <transmission name="left_arm_6_trans">
    <type>transmission_interface/SimpleTransmission</type>
    <joint name="left_arm_6_joint">
      <hardwareInterface>hardware_interface/EffortJointInterface</hardwareInterface>
      <hardwareInterface>hardware_interface/PositionJointInterface</hardwareInterface>
    </joint>
    <actuator name="left_arm_6_motor">
      <mechanicalReduction>1</mechanicalReduction>
    </actuator>
  </transmission>
  <joint name="left_asus_joint" type="fixed">
    <origin rpy="-3.1290897546768672 -0.06293262669010466 -0.007904165374966" xyz="0.08962811 -0.00032633 0.08260346"/>
    <parent link="left_arm_7_link"/>
    <child link="left_camera_link"/>
  </joint>
  <link name="left_camera_link">
    <inertial>
      <origin xyz="0 0 0"/>
      <mass value="0.2"/>
      <inertia ixx="0.02" ixy="0.0" ixz="0.0" iyy="0.02" iyz="0.0" izz="0.02"/>
    </inertial>
    <visual>
      <origin rpy="0 0 0.0" xyz="0 0 0"/>
      <geometry>
        <mesh filename="package://boris_description/meshes/asus_xtion_body.stl"/>
      </geometry>
      <material name="Boris/Black"/>
    </visual>
    <collision>
      <origin rpy="1.57079632679 0 0" xyz="0 0 0"/>
      <geometry>
        <cylinder length="0.20" radius="0.03"/>
      </geometry>
    </collision>
  </link>
  <!-- ASUS Xtion -->
  <link name="left_camera_depth_frame"/>
  <link name="left_camera_rgb_frame"/>
  <link name="left_camera_depth_optical_frame"/>
  <link name="left_camera_rgb_optical_frame"/>
  <joint name="left_camera_depth_frame_joint" type="fixed">
    <origin rpy="0 0 0" xyz="0 0.047 0.0"/>
    <parent link="left_camera_link"/>
    <child link="left_camera_depth_frame"/>
  </joint>
  <joint name="left_camera_rgb_frame_joint" type="fixed">
    <origin rpy="0.0 0.0 0.0" xyz="0 0.022 0.0"/>
    <parent link="left_camera_link"/>
    <child link="left_camera_rgb_frame"/>
  </joint>
  <joint name="left_camera_depth_optical_frame_joint" type="fixed">
    <origin rpy="-1.57079632679 0 -1.57079632679" xyz="0 0 0"/>
    <parent link="left_camera_depth_frame"/>
    <child link="left_camera_depth_optical_frame"/>
  </joint>
  <joint name="left_camera_rgb_optical_frame_joint" type="fixed">
    <origin rpy="-1.57079632679 0 -1.57079632679" xyz="0 0 0"/>
    <parent link="left_camera_rgb_frame"/>
    <child link="left_camera_rgb_optical_frame"/>
  </joint>
  <gazebo reference="left_camera_depth_frame">
    <sensor name="left_camera_gazebo_sensor" type="depth">
      <always_on>true</always_on>
      <update_rate>10.0</update_rate>
      <camera>
        <horizontal_fov>0.994837673637</horizontal_fov>
        <image>
          <format>B8G8R8</format>
          <width>640</width>
          <height>480</height>
        </image>
        <clip>
          <near>0.01</near>
          <far>5</far>
        </clip>
      </camera>
      <plugin filename="libgazebo_ros_openni_kinect.so" name="left_camera_link_controller">
        <alwaysOn>true</alwaysOn>
        <updateRate>0</updateRate>
        <cameraName>left_camera</cameraName>
        <imageTopicName>sim/rgb/image_raw</imageTopicName>
        <cameraInfoTopicName>sim/rgb/camera_info</cameraInfoTopicName>
        <depthImageTopicName>sim/depth/image_raw</depthImageTopicName>
        <depthImageCameraInfoTopicName>sim/depth/camera_info</depthImageCameraInfoTopicName>
        <pointCloudTopicName>sim/depth_registered/points</pointCloudTopicName>
        <frameName>left_camera_depth_optical_frame</frameName>
        <pointCloudCutoff>0.05</pointCloudCutoff>
        <distortionK1>0.0000000</distortionK1>
        <distortionK2>0.0000000</distortionK2>
        <distortionK3>0.0000000</distortionK3>
        <distortionT1>0.0000000</distortionT1>
        <distortionT2>0.0000000</distortionT2>
        <CxPrime>0</CxPrime>
        <Cx>0</Cx>
        <Cy>0</Cy>
        <focalLength>0</focalLength>
        <hackBaseline>0</hackBaseline>
      </plugin>
    </sensor>
  </gazebo>
  <link name="left_cable_guards">
    <inertial>
      <origin xyz="0.0 0.0 0.0"/>
      <mass value="0.1"/>
      <inertia ixx="1" ixy="0.0" ixz="0.0" iyy="1" iyz="0.0" izz="1"/>
    </inertial>
    <!-- real size 7.5 11.5 22.5 -->
    <visual>
      <origin rpy="0 0 0" xyz="0.0 0.0 0.0"/>
      <geometry>
        <box size="0.09 0.20 0.05"/>
      </geometry>
      <material name="Boris/Silver"/>
    </visual>
    <collision>
      <origin rpy="0 0 0" xyz="0.0 0.0 0.0"/>
      <box size="0.09 0.20 0.05"/>
      <geometry>
        <box size="0.09 0.20 0.05"/>
      </geometry>
    </collision>
  </link>
  <joint name="left_cable_guards_joint" type="fixed">
    <origin rpy="0 0 0" xyz="0 -0.035 0.04"/>
    <parent link="left_arm_7_link"/>
    <child link="left_cable_guards"/>
  </joint>
  <!-- LEFT SOFTHAND -->
  <link name="left_ft_sensor"/>
  <joint name="left_ft_sensor_joint" type="fixed">
    <origin rpy="0 0 0.785398163397" xyz="0 0.0 0.0"/>
    <parent link="left_arm_7_link"/>
    <child link="left_ft_sensor"/>
  </joint>
  <!-- PACMAN VERION ALREADY INCLUDES THE COUPLER, CLAMP AND BASE -->
  <joint name="left_ft_sensor_left_hand_kuka_coupler_joint" type="fixed">
    <origin rpy="0 0 -3.14159265359" xyz="0 0 0.072"/>
    <parent link="left_ft_sensor"/>
    <child link="left_hand_kuka_coupler_bottom"/>
  </joint>
  <link name="left_hand_kuka_coupler_bottom">
    <visual>
      <origin rpy="0 0 0" xyz="0 0 0.0115"/>
      <geometry>
        <!-- mesh filename="package://soft_hand_description/meshes/accesories/kuka_coupler.stl"/-->
        <cylinder length="0.023" radius="0.033"/>
      </geometry>
      <material name="SoftHand/Blue"/>
    </visual>
    <collision>
      <origin rpy="0 0 0" xyz="0 0 0.031"/>
      <geometry>
        <cylinder length="0.023" radius="0.033"/>
      </geometry>
    </collision>
  </link>
  <joint name="left_ft_sensor_left_hand_kuka_coupler_base_joint" type="fixed">
    <origin rpy="0 0 0" xyz="0 0 0.023"/>
    <parent link="left_hand_kuka_coupler_bottom"/>
    <child link="left_hand_kuka_coupler"/>
  </joint>
  <link name="left_hand_kuka_coupler"/>
  <joint name="left_hand_kuka_coupler_left_hand_clamp_joint" type="fixed">
    <origin rpy="0 0 0" xyz="0 0 0.01"/>
    <parent link="left_hand_kuka_coupler"/>
    <child link="left_hand_clamp"/>
  </joint>
  <link name="left_hand_clamp">
    <visual>
      <origin rpy="0 0 0" xyz="0 0 0"/>
      <geometry>
        <mesh filename="package://soft_hand_description/meshes/accesories/clamp.stl"/>
      </geometry>
      <material name="SoftHand/Blue"/>
    </visual>
    <collision>
      <origin rpy="0 0 0" xyz="0 0 0"/>
      <geometry>
        <box size="0.066 0.0725 0.0256"/>
      </geometry>
    </collision>
  </link>
  <joint name="left_hand_clamp_left_hand_softhand_base_joint" type="fixed">
    <origin rpy="0 0 0" xyz="0 0 0.004"/>
    <parent link="left_hand_clamp"/>
    <child link="left_hand_softhand_base"/>
  </joint>
  <link name="left_hand_softhand_base">
    <visual>
      <origin rpy="0 0 0" xyz="0 0 0"/>
      <geometry>
        <mesh filename="package://soft_hand_description/meshes/accesories/softhand_base_right.stl"/>
      </geometry>
      <material name="SoftHand/Blue"/>
    </visual>
    <collision>
      <origin rpy="0 0 0" xyz="0 0 0.031"/>
      <geometry>
        <box size="0.066 0.066 0.062"/>
      </geometry>
    </collision>
  </link>
  <!-- PALM -->
  <joint name="left_hand_palm_joint" type="fixed">
    <origin rpy="0 0 0" xyz="0.002 0.00695 0.0535"/>
    <parent link="left_hand_softhand_base"/>
    <child link="left_hand_palm_link"/>
  </joint>
  <link name="left_hand_palm_link">
    <inertial>
      <origin xyz="-0.004568758 -0.006808116 0.027653328"/>
      <mass value="0.228"/>
      <inertia ixx="0.16302" ixy="0.00228" ixz="0.00228" iyy="0.09462" iyz="0.00456" izz="0.11058"/>
    </inertial>
    <visual>
      <geometry>
        <mesh filename="package://soft_hand_description/meshes/palm_right.stl" scale=" .001 .001 .001"/>
      </geometry>
      <material name="SoftHand/DarkGrey"/>
    </visual>
    <collision>
      <geometry>
        <mesh filename="package://soft_hand_description/meshes/palm_right_collision.stl" scale=" .001 .001 .001"/>
      </geometry>
    </collision>
  </link>
  <!-- MOTOR JOINT -->
  <joint name="left_hand_synergy_joint" type="revolute">
    <parent link="left_hand_palm_link"/>
    <child link="left_hand_invisible_wire_link"/>
    <axis xyz="0 0 1"/>
    <limit effort="100" lower="0.0" upper="1.0" velocity="100000"/>
    <dynamics damping="0.0" friction="0.0"/>
  </joint>
  <link name="left_hand_invisible_wire_link">
    <inertial>
      <origin xyz="0 0 0"/>
      <mass value="0.2"/>
      <inertia ixx="0.02" ixy="0.0" ixz="0.0" iyy="0.02" iyz="0.0" izz="0.02"/>
    </inertial>
  </link>
  <!-- KNUCKLE -->
  <joint name="left_hand_thumb_abd_joint" type="revolute">
    <origin rpy="0.0 -0.38397275793662144 1.5707963267948966" xyz="0.00566972 0.0296160 0.0553140"/>
    <parent link="left_hand_palm_link"/>
    <child link="left_hand_thumb_knuckle_link"/>
    <axis xyz="0 0 -1"/>
    <limit effort="100" lower="0.0" upper="1.57079632679" velocity="100"/>
    <dynamics damping="0.0" friction="0.0"/>
    <mimic joint="left_hand_synergy_joint" multiplier="2.04203522483"/>
  </joint>
  <link name="left_hand_thumb_knuckle_link">
    <inertial>
      <origin xyz="0.013608098 -0.000532174 -0.000216691"/>
      <mass value="0.009"/>
      <inertia ixx="0.000315" ixy="2.7e-05" ixz="-5.4e-05" iyy="0.0009" iyz="1.8e-05" izz="0.0009"/>
    </inertial>
    <visual>
      <geometry>
        <mesh filename="package://soft_hand_description/meshes/thumb_knuckle_right.stl" scale=" .001 .001 .001"/>
      </geometry>
      <material name="SoftHand/DarkGrey"/>
    </visual>
    <collision>
      <geometry>
        <mesh filename="package://soft_hand_description/meshes/thumb_knuckle_right_collision.stl" scale=" .001 .001 .001"/>
      </geometry>
    </collision>
  </link>
  <!-- PROXIMAL PHALANGE -->
  <joint name="left_hand_thumb_inner_joint" type="revolute">
    <!-- <origin xyz="0.022500000 -0.003300000 0.0" rpy="0.42662757656587236 0.0 0.18131960430075023" /> -->
    <origin rpy="0.42662757656587236 0.0 0.0" xyz="0.022500000 -0.003300000 0.0"/>
    <parent link="left_hand_thumb_knuckle_link"/>
    <child link="left_hand_thumb_fake_link1"/>
    <axis xyz="0 -1 0"/>
    <limit effort="100" lower="0.0" upper="0.785398163397" velocity="100"/>
    <dynamics damping="0.0" friction="0.0"/>
    <mimic joint="left_hand_synergy_joint" multiplier="1.02101761242"/>
  </joint>
  <link name="left_hand_thumb_fake_link1">
    <inertial>
      <origin xyz="0 0 0"/>
      <mass value="0.2"/>
      <inertia ixx="0.02" ixy="0.0" ixz="0.0" iyy="0.02" iyz="0.0" izz="0.02"/>
    </inertial>
  </link>
  <joint name="left_hand_thumb_inner_joint_mimic" type="revolute">
    <origin rpy="0 0 0" xyz="0.013 0 0"/>
    <parent link="left_hand_thumb_fake_link1"/>
    <child link="left_hand_thumb_proximal_link"/>
    <axis xyz="0 -1 0"/>
    <limit effort="100" lower="0.0" upper="0.785398163397" velocity="100"/>
    <dynamics damping="0.0" friction="0.0"/>
    <mimic joint="left_hand_synergy_joint" multiplier="1.02101761242"/>
  </joint>
  <link name="left_hand_thumb_proximal_link">
    <inertial>
      <origin xyz="0.005074337 -4.524e-06 -0.000262953"/>
      <mass value="0.005"/>
      <inertia ixx="0.000175" ixy="0.0" ixz="1e-05" iyy="0.000275" iyz="0.0" izz="0.000275"/>
    </inertial>
    <visual>
      <geometry>
        <mesh filename="package://soft_hand_description/meshes/phalanx.stl" scale=" .001 .001 .001"/>
      </geometry>
      <material name="SoftHand/DarkGrey"/>
    </visual>
    <collision>
      <geometry>
        <mesh filename="package://soft_hand_description/meshes/phalanx_collision.stl" scale=" .001 .001 .001"/>
      </geometry>
    </collision>
  </link>
  <!-- DISTAL PHALANGE -->
  <joint name="left_hand_thumb_outer_joint" type="revolute">
    <origin rpy="0 0 0" xyz="0.009 0 0.0"/>
    <parent link="left_hand_thumb_proximal_link"/>
    <child link="left_hand_thumb_fake_link3"/>
    <axis xyz="0 -1 0"/>
    <limit effort="100" lower="0.0" upper="0.785398163397" velocity="100"/>
    <dynamics damping="0.0" friction="0.0"/>
    <mimic joint="left_hand_synergy_joint" multiplier="0.785398163397"/>
  </joint>
  <link name="left_hand_thumb_fake_link3">
    <inertial>
      <origin xyz="0 0 0"/>
      <mass value="0.2"/>
      <inertia ixx="0.02" ixy="0.0" ixz="0.0" iyy="0.02" iyz="0.0" izz="0.02"/>
    </inertial>
  </link>
  <joint name="left_hand_thumb_outer_joint_mimic" type="revolute">
    <origin rpy="0 0 0" xyz="0.013 0 0"/>
    <parent link="left_hand_thumb_fake_link3"/>
    <child link="left_hand_thumb_distal_link"/>
    <axis xyz="0 -1 0"/>
    <limit effort="100" lower="0.0" upper="0.785398163397" velocity="100"/>
    <dynamics damping="0.0" friction="0.0"/>
    <mimic joint="left_hand_synergy_joint" multiplier="0.785398163397"/>
  </joint>
  <link name="left_hand_thumb_distal_link">
    <inertial>
      <origin xyz="0.009849094 5.6e-07 0.000820286"/>
      <mass value="0.01"/>
      <inertia ixx="0.00035" ixy="0.0" ixz="2e-05" iyy="0.0008" iyz="0.0" izz="0.00076"/>
    </inertial>
    <visual>
      <geometry>
        <mesh filename="package://soft_hand_description/meshes/fingertip.stl" scale=" .001 .001 .001"/>
      </geometry>
      <material name="SoftHand/DarkGrey"/>
    </visual>
    <collision>
      <geometry>
        <mesh filename="package://soft_hand_description/meshes/fingertip_collision.stl" scale=" .001 .001 .001"/>
      </geometry>
    </collision>
  </link>
  <!-- KNUCKLE -->
  <joint name="left_hand_index_abd_joint" type="revolute">
    <origin rpy="1.5707963267948966 -1.4835299330931884 1.5707963267948966" xyz="-0.0033 0.0195 0.0936994"/>
    <parent link="left_hand_palm_link"/>
    <child link="left_hand_index_knuckle_link"/>
    <axis xyz="0 0 1"/>
    <limit effort="100" lower="-0.523598775598" upper="0.523598775598" velocity="100"/>
    <dynamics damping="0.0" friction="0.0"/>
    <mimic joint="left_hand_synergy_joint" multiplier="-0.2"/>
  </joint>
  <link name="left_hand_index_knuckle_link">
    <inertial>
      <origin xyz="0.001285644 -9.58e-07 0.000425011"/>
      <mass value="0.009"/>
      <inertia ixx="0.000405" ixy="0.0" ixz="4.5e-05" iyy="0.00081" iyz="0.0" izz="0.00063"/>
    </inertial>
    <visual>
      <geometry>
        <mesh filename="package://soft_hand_description/meshes/knuckle.stl" scale=" .001 .001 .001"/>
      </geometry>
      <material name="SoftHand/DarkGrey"/>
    </visual>
    <collision>
      <geometry>
        <mesh filename="package://soft_hand_description/meshes/knuckle_collision.stl" scale=" .001 .001 .001"/>
      </geometry>
    </collision>
  </link>
  <!-- PROXIMAL PHALANGE -->
  <joint name="left_hand_index_inner_joint" type="revolute">
    <origin rpy="0 0 0" xyz="0.009 0 0"/>
    <parent link="left_hand_index_knuckle_link"/>
    <child link="left_hand_index_fake_link1"/>
    <axis xyz="0 -1 0"/>
    <limit effort="100" lower="0.0" upper="0.785398163397" velocity="100"/>
    <dynamics damping="0.0" friction="0.0"/>
    <mimic joint="left_hand_synergy_joint" multiplier="0.785398163397"/>
  </joint>
  <link name="left_hand_index_fake_link1">
    <inertial>
      <origin xyz="0 0 0"/>
      <mass value="0.2"/>
      <inertia ixx="0.02" ixy="0.0" ixz="0.0" iyy="0.02" iyz="0.0" izz="0.02"/>
    </inertial>
  </link>
  <joint name="left_hand_index_inner_joint_mimic" type="revolute">
    <origin rpy="0 0 0" xyz="0.013 0 0"/>
    <parent link="left_hand_index_fake_link1"/>
    <child link="left_hand_index_proximal_link"/>
    <axis xyz="0 -1 0"/>
    <limit effort="100" lower="0.0" upper="0.785398163397" velocity="100"/>
    <dynamics damping="0.0" friction="0.0"/>
    <mimic joint="left_hand_synergy_joint" multiplier="0.785398163397"/>
  </joint>
  <link name="left_hand_index_proximal_link">
    <inertial>
      <origin xyz="0.005074337 -4.524e-06 -0.000262953"/>
      <mass value="0.005"/>
      <inertia ixx="0.000175" ixy="0.0" ixz="1e-05" iyy="0.000275" iyz="0.0" izz="0.000275"/>
    </inertial>
    <visual>
      <geometry>
        <mesh filename="package://soft_hand_description/meshes/phalanx.stl" scale=" .001 .001 .001"/>
      </geometry>
      <material name="SoftHand/DarkGrey"/>
    </visual>
    <collision>
      <geometry>
        <mesh filename="package://soft_hand_description/meshes/phalanx_collision.stl" scale=" .001 .001 .001"/>
      </geometry>
    </collision>
  </link>
  <!-- MIDDLE PHALANGE -->
  <joint name="left_hand_index_middle_joint" type="revolute">
    <origin rpy="0 0 0" xyz="0.009 0 0"/>
    <parent link="left_hand_index_proximal_link"/>
    <child link="left_hand_index_fake_link2"/>
    <axis xyz="0 -1 0"/>
    <limit effort="100" lower="0.0" upper="0.785398163397" velocity="100"/>
    <dynamics damping="0.0" friction="0.0"/>
    <mimic joint="left_hand_synergy_joint" multiplier="0.785398163397"/>
  </joint>
  <link name="left_hand_index_fake_link2">
    <inertial>
      <origin xyz="0 0 0"/>
      <mass value="0.2"/>
      <inertia ixx="0.02" ixy="0.0" ixz="0.0" iyy="0.02" iyz="0.0" izz="0.02"/>
    </inertial>
  </link>
  <joint name="left_hand_index_middle_joint_mimic" type="revolute">
    <origin rpy="0 0 0" xyz="0.013 0 0"/>
    <parent link="left_hand_index_fake_link2"/>
    <child link="left_hand_index_middle_link"/>
    <axis xyz="0 -1 0"/>
    <limit effort="100" lower="0.0" upper="0.785398163397" velocity="100"/>
    <dynamics damping="0.0" friction="0.0"/>
    <mimic joint="left_hand_synergy_joint" multiplier="0.785398163397"/>
  </joint>
  <link name="left_hand_index_middle_link">
    <inertial>
      <origin xyz="0.005074337 -4.524e-06 -0.000262953"/>
      <mass value="0.005"/>
      <inertia ixx="0.000175" ixy="0.0" ixz="1e-05" iyy="0.000275" iyz="0.0" izz="0.000275"/>
    </inertial>
    <visual>
      <geometry>
        <mesh filename="package://soft_hand_description/meshes/phalanx.stl" scale=" .001 .001 .001"/>
      </geometry>
      <material name="SoftHand/DarkGrey"/>
    </visual>
    <collision>
      <geometry>
        <mesh filename="package://soft_hand_description/meshes/phalanx_collision.stl" scale=" .001 .001 .001"/>
      </geometry>
    </collision>
  </link>
  <!-- DISTAL PHALANGE -->
  <joint name="left_hand_index_outer_joint" type="revolute">
    <origin rpy="0 0 0" xyz="0.009 0 0"/>
    <parent link="left_hand_index_middle_link"/>
    <child link="left_hand_index_fake_link3"/>
    <axis xyz="0 -1 0"/>
    <limit effort="100" lower="0.0" upper="0.785398163397" velocity="100"/>
    <dynamics damping="0.0" friction="0.0"/>
    <mimic joint="left_hand_synergy_joint" multiplier="0.785398163397"/>
  </joint>
  <link name="left_hand_index_fake_link3">
    <inertial>
      <origin xyz="0 0 0"/>
      <mass value="0.2"/>
      <inertia ixx="0.02" ixy="0.0" ixz="0.0" iyy="0.02" iyz="0.0" izz="0.02"/>
    </inertial>
  </link>
  <joint name="left_hand_index_outer_joint_mimic" type="revolute">
    <origin rpy="0 0 0" xyz="0.013 0 0"/>
    <parent link="left_hand_index_fake_link3"/>
    <child link="left_hand_index_distal_link"/>
    <axis xyz="0 -1 0"/>
    <limit effort="100" lower="0.0" upper="0.785398163397" velocity="100"/>
    <dynamics damping="0.0" friction="0.0"/>
    <mimic joint="left_hand_synergy_joint" multiplier="0.785398163397"/>
  </joint>
  <link name="left_hand_index_distal_link">
    <inertial>
      <origin xyz="0.009849094 5.6e-07 0.000820286"/>
      <mass value="0.01"/>
      <inertia ixx="0.00035" ixy="0.0" ixz="2e-05" iyy="0.0008" iyz="0.0" izz="0.00076"/>
    </inertial>
    <visual>
      <geometry>
        <mesh filename="package://soft_hand_description/meshes/fingertip.stl" scale=" .001 .001 .001"/>
      </geometry>
      <material name="SoftHand/DarkGrey"/>
    </visual>
    <collision>
      <geometry>
        <mesh filename="package://soft_hand_description/meshes/fingertip_collision.stl" scale=" .001 .001 .001"/>
      </geometry>
    </collision>
  </link>
  <!-- KNUCKLE -->
  <joint name="left_hand_middle_abd_joint" type="revolute">
    <origin rpy="3.141592 -1.5707963267948966 0.0" xyz="-0.003300000 0.0 0.100699"/>
    <parent link="left_hand_palm_link"/>
    <child link="left_hand_middle_knuckle_link"/>
    <axis xyz="0 0 1"/>
    <limit effort="100" lower="-0.523598775598" upper="0.523598775598" velocity="100"/>
    <dynamics damping="0.0" friction="0.0"/>
    <mimic joint="left_hand_synergy_joint" multiplier="0.0"/>
  </joint>
  <link name="left_hand_middle_knuckle_link">
    <inertial>
      <origin xyz="0.001285644 -9.58e-07 0.000425011"/>
      <mass value="0.009"/>
      <inertia ixx="0.000405" ixy="0.0" ixz="4.5e-05" iyy="0.00081" iyz="0.0" izz="0.00063"/>
    </inertial>
    <visual>
      <geometry>
        <mesh filename="package://soft_hand_description/meshes/knuckle.stl" scale=" .001 .001 .001"/>
      </geometry>
      <material name="SoftHand/DarkGrey"/>
    </visual>
    <collision>
      <geometry>
        <mesh filename="package://soft_hand_description/meshes/knuckle_collision.stl" scale=" .001 .001 .001"/>
      </geometry>
    </collision>
  </link>
  <!-- PROXIMAL PHALANGE -->
  <joint name="left_hand_middle_inner_joint" type="revolute">
    <origin rpy="0 0 0" xyz="0.009 0 0"/>
    <parent link="left_hand_middle_knuckle_link"/>
    <child link="left_hand_middle_fake_link1"/>
    <axis xyz="0 -1 0"/>
    <limit effort="100" lower="0.0" upper="0.785398163397" velocity="100"/>
    <dynamics damping="0.0" friction="0.0"/>
    <mimic joint="left_hand_synergy_joint" multiplier="0.785398163397"/>
  </joint>
  <link name="left_hand_middle_fake_link1">
    <inertial>
      <origin xyz="0 0 0"/>
      <mass value="0.2"/>
      <inertia ixx="0.02" ixy="0.0" ixz="0.0" iyy="0.02" iyz="0.0" izz="0.02"/>
    </inertial>
  </link>
  <joint name="left_hand_middle_inner_joint_mimic" type="revolute">
    <origin rpy="0 0 0" xyz="0.013 0 0"/>
    <parent link="left_hand_middle_fake_link1"/>
    <child link="left_hand_middle_proximal_link"/>
    <axis xyz="0 -1 0"/>
    <limit effort="100" lower="0.0" upper="0.785398163397" velocity="100"/>
    <dynamics damping="0.0" friction="0.0"/>
    <mimic joint="left_hand_synergy_joint" multiplier="0.785398163397"/>
  </joint>
  <link name="left_hand_middle_proximal_link">
    <inertial>
      <origin xyz="0.005074337 -4.524e-06 -0.000262953"/>
      <mass value="0.005"/>
      <inertia ixx="0.000175" ixy="0.0" ixz="1e-05" iyy="0.000275" iyz="0.0" izz="0.000275"/>
    </inertial>
    <visual>
      <geometry>
        <mesh filename="package://soft_hand_description/meshes/phalanx.stl" scale=" .001 .001 .001"/>
      </geometry>
      <material name="SoftHand/DarkGrey"/>
    </visual>
    <collision>
      <geometry>
        <mesh filename="package://soft_hand_description/meshes/phalanx_collision.stl" scale=" .001 .001 .001"/>
      </geometry>
    </collision>
  </link>
  <!-- MIDDLE PHALANGE -->
  <joint name="left_hand_middle_middle_joint" type="revolute">
    <origin rpy="0 0 0" xyz="0.009 0 0"/>
    <parent link="left_hand_middle_proximal_link"/>
    <child link="left_hand_middle_fake_link2"/>
    <axis xyz="0 -1 0"/>
    <limit effort="100" lower="0.0" upper="0.785398163397" velocity="100"/>
    <dynamics damping="0.0" friction="0.0"/>
    <mimic joint="left_hand_synergy_joint" multiplier="0.785398163397"/>
  </joint>
  <link name="left_hand_middle_fake_link2">
    <inertial>
      <origin xyz="0 0 0"/>
      <mass value="0.2"/>
      <inertia ixx="0.02" ixy="0.0" ixz="0.0" iyy="0.02" iyz="0.0" izz="0.02"/>
    </inertial>
  </link>
  <joint name="left_hand_middle_middle_joint_mimic" type="revolute">
    <origin rpy="0 0 0" xyz="0.013 0 0"/>
    <parent link="left_hand_middle_fake_link2"/>
    <child link="left_hand_middle_middle_link"/>
    <axis xyz="0 -1 0"/>
    <limit effort="100" lower="0.0" upper="0.785398163397" velocity="100"/>
    <dynamics damping="0.0" friction="0.0"/>
    <mimic joint="left_hand_synergy_joint" multiplier="0.785398163397"/>
  </joint>
  <link name="left_hand_middle_middle_link">
    <inertial>
      <origin xyz="0.005074337 -4.524e-06 -0.000262953"/>
      <mass value="0.005"/>
      <inertia ixx="0.000175" ixy="0.0" ixz="1e-05" iyy="0.000275" iyz="0.0" izz="0.000275"/>
    </inertial>
    <visual>
      <geometry>
        <mesh filename="package://soft_hand_description/meshes/phalanx.stl" scale=" .001 .001 .001"/>
      </geometry>
      <material name="SoftHand/DarkGrey"/>
    </visual>
    <collision>
      <geometry>
        <mesh filename="package://soft_hand_description/meshes/phalanx_collision.stl" scale=" .001 .001 .001"/>
      </geometry>
    </collision>
  </link>
  <!-- DISTAL PHALANGE -->
  <joint name="left_hand_middle_outer_joint" type="revolute">
    <origin rpy="0 0 0" xyz="0.009 0 0"/>
    <parent link="left_hand_middle_middle_link"/>
    <child link="left_hand_middle_fake_link3"/>
    <axis xyz="0 -1 0"/>
    <limit effort="100" lower="0.0" upper="0.785398163397" velocity="100"/>
    <dynamics damping="0.0" friction="0.0"/>
    <mimic joint="left_hand_synergy_joint" multiplier="0.785398163397"/>
  </joint>
  <link name="left_hand_middle_fake_link3">
    <inertial>
      <origin xyz="0 0 0"/>
      <mass value="0.2"/>
      <inertia ixx="0.02" ixy="0.0" ixz="0.0" iyy="0.02" iyz="0.0" izz="0.02"/>
    </inertial>
  </link>
  <joint name="left_hand_middle_outer_joint_mimic" type="revolute">
    <origin rpy="0 0 0" xyz="0.013 0 0"/>
    <parent link="left_hand_middle_fake_link3"/>
    <child link="left_hand_middle_distal_link"/>
    <axis xyz="0 -1 0"/>
    <limit effort="100" lower="0.0" upper="0.785398163397" velocity="100"/>
    <dynamics damping="0.0" friction="0.0"/>
    <mimic joint="left_hand_synergy_joint" multiplier="0.785398163397"/>
  </joint>
  <link name="left_hand_middle_distal_link">
    <inertial>
      <origin xyz="0.009849094 5.6e-07 0.000820286"/>
      <mass value="0.01"/>
      <inertia ixx="0.00035" ixy="0.0" ixz="2e-05" iyy="0.0008" iyz="0.0" izz="0.00076"/>
    </inertial>
    <visual>
      <geometry>
        <mesh filename="package://soft_hand_description/meshes/fingertip.stl" scale=" .001 .001 .001"/>
      </geometry>
      <material name="SoftHand/DarkGrey"/>
    </visual>
    <collision>
      <geometry>
        <mesh filename="package://soft_hand_description/meshes/fingertip_collision.stl" scale=" .001 .001 .001"/>
      </geometry>
    </collision>
  </link>
  <!-- KNUCKLE -->
  <joint name="left_hand_ring_abd_joint" type="revolute">
    <origin rpy="-1.5707963267948966 -1.5184364298870514 -1.5707963267948966 " xyz="-0.0033 -0.0195 0.0936994"/>
    <parent link="left_hand_palm_link"/>
    <child link="left_hand_ring_knuckle_link"/>
    <axis xyz="0 0 1"/>
    <limit effort="100" lower="-0.523598775598" upper="0.523598775598" velocity="100"/>
    <dynamics damping="0.0" friction="0.0"/>
    <mimic joint="left_hand_synergy_joint" multiplier="0.2"/>
  </joint>
  <link name="left_hand_ring_knuckle_link">
    <inertial>
      <origin xyz="0.001285644 -9.58e-07 0.000425011"/>
      <mass value="0.009"/>
      <inertia ixx="0.000405" ixy="0.0" ixz="4.5e-05" iyy="0.00081" iyz="0.0" izz="0.00063"/>
    </inertial>
    <visual>
      <geometry>
        <mesh filename="package://soft_hand_description/meshes/knuckle.stl" scale=" .001 .001 .001"/>
      </geometry>
      <material name="SoftHand/DarkGrey"/>
    </visual>
    <collision>
      <geometry>
        <mesh filename="package://soft_hand_description/meshes/knuckle_collision.stl" scale=" .001 .001 .001"/>
      </geometry>
    </collision>
  </link>
  <!-- PROXIMAL PHALANGE -->
  <joint name="left_hand_ring_inner_joint" type="revolute">
    <origin rpy="0 0 0" xyz="0.009 0 0"/>
    <parent link="left_hand_ring_knuckle_link"/>
    <child link="left_hand_ring_fake_link1"/>
    <axis xyz="0 -1 0"/>
    <limit effort="100" lower="0.0" upper="0.785398163397" velocity="100"/>
    <dynamics damping="0.0" friction="0.0"/>
    <mimic joint="left_hand_synergy_joint" multiplier="0.785398163397"/>
  </joint>
  <link name="left_hand_ring_fake_link1">
    <inertial>
      <origin xyz="0 0 0"/>
      <mass value="0.2"/>
      <inertia ixx="0.02" ixy="0.0" ixz="0.0" iyy="0.02" iyz="0.0" izz="0.02"/>
    </inertial>
  </link>
  <joint name="left_hand_ring_inner_joint_mimic" type="revolute">
    <origin rpy="0 0 0" xyz="0.013 0 0"/>
    <parent link="left_hand_ring_fake_link1"/>
    <child link="left_hand_ring_proximal_link"/>
    <axis xyz="0 -1 0"/>
    <limit effort="100" lower="0.0" upper="0.785398163397" velocity="100"/>
    <dynamics damping="0.0" friction="0.0"/>
    <mimic joint="left_hand_synergy_joint" multiplier="0.785398163397"/>
  </joint>
  <link name="left_hand_ring_proximal_link">
    <inertial>
      <origin xyz="0.005074337 -4.524e-06 -0.000262953"/>
      <mass value="0.005"/>
      <inertia ixx="0.000175" ixy="0.0" ixz="1e-05" iyy="0.000275" iyz="0.0" izz="0.000275"/>
    </inertial>
    <visual>
      <geometry>
        <mesh filename="package://soft_hand_description/meshes/phalanx.stl" scale=" .001 .001 .001"/>
      </geometry>
      <material name="SoftHand/DarkGrey"/>
    </visual>
    <collision>
      <geometry>
        <mesh filename="package://soft_hand_description/meshes/phalanx_collision.stl" scale=" .001 .001 .001"/>
      </geometry>
    </collision>
  </link>
  <!-- MIDDLE PHALANGE -->
  <joint name="left_hand_ring_middle_joint" type="revolute">
    <origin rpy="0 0 0" xyz="0.009 0 0"/>
    <parent link="left_hand_ring_proximal_link"/>
    <child link="left_hand_ring_fake_link2"/>
    <axis xyz="0 -1 0"/>
    <limit effort="100" lower="0.0" upper="0.785398163397" velocity="100"/>
    <dynamics damping="0.0" friction="0.0"/>
    <mimic joint="left_hand_synergy_joint" multiplier="0.785398163397"/>
  </joint>
  <link name="left_hand_ring_fake_link2">
    <inertial>
      <origin xyz="0 0 0"/>
      <mass value="0.2"/>
      <inertia ixx="0.02" ixy="0.0" ixz="0.0" iyy="0.02" iyz="0.0" izz="0.02"/>
    </inertial>
  </link>
  <joint name="left_hand_ring_middle_joint_mimic" type="revolute">
    <origin rpy="0 0 0" xyz="0.013 0 0"/>
    <parent link="left_hand_ring_fake_link2"/>
    <child link="left_hand_ring_middle_link"/>
    <axis xyz="0 -1 0"/>
    <limit effort="100" lower="0.0" upper="0.785398163397" velocity="100"/>
    <dynamics damping="0.0" friction="0.0"/>
    <mimic joint="left_hand_synergy_joint" multiplier="0.785398163397"/>
  </joint>
  <link name="left_hand_ring_middle_link">
    <inertial>
      <origin xyz="0.005074337 -4.524e-06 -0.000262953"/>
      <mass value="0.005"/>
      <inertia ixx="0.000175" ixy="0.0" ixz="1e-05" iyy="0.000275" iyz="0.0" izz="0.000275"/>
    </inertial>
    <visual>
      <geometry>
        <mesh filename="package://soft_hand_description/meshes/phalanx.stl" scale=" .001 .001 .001"/>
      </geometry>
      <material name="SoftHand/DarkGrey"/>
    </visual>
    <collision>
      <geometry>
        <mesh filename="package://soft_hand_description/meshes/phalanx_collision.stl" scale=" .001 .001 .001"/>
      </geometry>
    </collision>
  </link>
  <!-- DISTAL PHALANGE -->
  <joint name="left_hand_ring_outer_joint" type="revolute">
    <origin rpy="0 0 0" xyz="0.009 0 0"/>
    <parent link="left_hand_ring_middle_link"/>
    <child link="left_hand_ring_fake_link3"/>
    <axis xyz="0 -1 0"/>
    <limit effort="100" lower="0.0" upper="0.785398163397" velocity="100"/>
    <dynamics damping="0.0" friction="0.0"/>
    <mimic joint="left_hand_synergy_joint" multiplier="0.785398163397"/>
  </joint>
  <link name="left_hand_ring_fake_link3">
    <inertial>
      <origin xyz="0 0 0"/>
      <mass value="0.2"/>
      <inertia ixx="0.02" ixy="0.0" ixz="0.0" iyy="0.02" iyz="0.0" izz="0.02"/>
    </inertial>
  </link>
  <joint name="left_hand_ring_outer_joint_mimic" type="revolute">
    <origin rpy="0 0 0" xyz="0.013 0 0"/>
    <parent link="left_hand_ring_fake_link3"/>
    <child link="left_hand_ring_distal_link"/>
    <axis xyz="0 -1 0"/>
    <limit effort="100" lower="0.0" upper="0.785398163397" velocity="100"/>
    <dynamics damping="0.0" friction="0.0"/>
    <mimic joint="left_hand_synergy_joint" multiplier="0.785398163397"/>
  </joint>
  <link name="left_hand_ring_distal_link">
    <inertial>
      <origin xyz="0.009849094 5.6e-07 0.000820286"/>
      <mass value="0.01"/>
      <inertia ixx="0.00035" ixy="0.0" ixz="2e-05" iyy="0.0008" iyz="0.0" izz="0.00076"/>
    </inertial>
    <visual>
      <geometry>
        <mesh filename="package://soft_hand_description/meshes/fingertip.stl" scale=" .001 .001 .001"/>
      </geometry>
      <material name="SoftHand/DarkGrey"/>
    </visual>
    <collision>
      <geometry>
        <mesh filename="package://soft_hand_description/meshes/fingertip_collision.stl" scale=" .001 .001 .001"/>
      </geometry>
    </collision>
  </link>
  <!-- KNUCKLE -->
  <joint name="left_hand_little_abd_joint" type="revolute">
    <origin rpy="-1.5707963267948966 -1.4835299330931884 -1.5707963267948966" xyz="-0.0033 -0.039 0.0836994"/>
    <parent link="left_hand_palm_link"/>
    <child link="left_hand_little_knuckle_link"/>
    <axis xyz="0 0 1"/>
    <limit effort="100" lower="-0.523598775598" upper="0.523598775598" velocity="100"/>
    <dynamics damping="0.0" friction="0.0"/>
    <mimic joint="left_hand_synergy_joint" multiplier="0.4"/>
  </joint>
  <link name="left_hand_little_knuckle_link">
    <inertial>
      <origin xyz="0.001285644 -9.58e-07 0.000425011"/>
      <mass value="0.009"/>
      <inertia ixx="0.000405" ixy="0.0" ixz="4.5e-05" iyy="0.00081" iyz="0.0" izz="0.00063"/>
    </inertial>
    <visual>
      <geometry>
        <mesh filename="package://soft_hand_description/meshes/knuckle.stl" scale=" .001 .001 .001"/>
      </geometry>
      <material name="SoftHand/DarkGrey"/>
    </visual>
    <collision>
      <geometry>
        <mesh filename="package://soft_hand_description/meshes/knuckle_collision.stl" scale=" .001 .001 .001"/>
      </geometry>
    </collision>
  </link>
  <!-- PROXIMAL PHALANGE -->
  <joint name="left_hand_little_inner_joint" type="revolute">
    <origin rpy="0 0 0" xyz="0.009 0 0"/>
    <parent link="left_hand_little_knuckle_link"/>
    <child link="left_hand_little_fake_link1"/>
    <axis xyz="0 -1 0"/>
    <limit effort="100" lower="0.0" upper="0.785398163397" velocity="100"/>
    <dynamics damping="0.0" friction="0.0"/>
    <mimic joint="left_hand_synergy_joint" multiplier="0.785398163397"/>
  </joint>
  <link name="left_hand_little_fake_link1">
    <inertial>
      <origin xyz="0 0 0"/>
      <mass value="0.2"/>
      <inertia ixx="0.02" ixy="0.0" ixz="0.0" iyy="0.02" iyz="0.0" izz="0.02"/>
    </inertial>
  </link>
  <joint name="left_hand_little_inner_joint_mimic" type="revolute">
    <origin rpy="0 0 0" xyz="0.013 0 0"/>
    <parent link="left_hand_little_fake_link1"/>
    <child link="left_hand_little_proximal_link"/>
    <axis xyz="0 -1 0"/>
    <limit effort="100" lower="0.0" upper="0.785398163397" velocity="100"/>
    <dynamics damping="0.0" friction="0.0"/>
    <mimic joint="left_hand_synergy_joint" multiplier="0.785398163397"/>
  </joint>
  <link name="left_hand_little_proximal_link">
    <inertial>
      <origin xyz="0.005074337 -4.524e-06 -0.000262953"/>
      <mass value="0.005"/>
      <inertia ixx="0.000175" ixy="0.0" ixz="1e-05" iyy="0.000275" iyz="0.0" izz="0.000275"/>
    </inertial>
    <visual>
      <geometry>
        <mesh filename="package://soft_hand_description/meshes/phalanx.stl" scale=" .001 .001 .001"/>
      </geometry>
      <material name="SoftHand/DarkGrey"/>
    </visual>
    <collision>
      <geometry>
        <mesh filename="package://soft_hand_description/meshes/phalanx_collision.stl" scale=" .001 .001 .001"/>
      </geometry>
    </collision>
  </link>
  <!-- MIDDLE PHALANGE -->
  <joint name="left_hand_little_middle_joint" type="revolute">
    <origin rpy="0 0 0" xyz="0.009 0 0"/>
    <parent link="left_hand_little_proximal_link"/>
    <child link="left_hand_little_fake_link2"/>
    <axis xyz="0 -1 0"/>
    <limit effort="100" lower="0.0" upper="0.785398163397" velocity="100"/>
    <dynamics damping="0.0" friction="0.0"/>
    <mimic joint="left_hand_synergy_joint" multiplier="0.785398163397"/>
  </joint>
  <link name="left_hand_little_fake_link2">
    <inertial>
      <origin xyz="0 0 0"/>
      <mass value="0.2"/>
      <inertia ixx="0.02" ixy="0.0" ixz="0.0" iyy="0.02" iyz="0.0" izz="0.02"/>
    </inertial>
  </link>
  <joint name="left_hand_little_middle_joint_mimic" type="revolute">
    <origin rpy="0 0 0" xyz="0.013 0 0"/>
    <parent link="left_hand_little_fake_link2"/>
    <child link="left_hand_little_middle_link"/>
    <axis xyz="0 -1 0"/>
    <limit effort="100" lower="0.0" upper="0.785398163397" velocity="100"/>
    <dynamics damping="0.0" friction="0.0"/>
    <mimic joint="left_hand_synergy_joint" multiplier="0.785398163397"/>
  </joint>
  <link name="left_hand_little_middle_link">
    <inertial>
      <origin xyz="0.005074337 -4.524e-06 -0.000262953"/>
      <mass value="0.005"/>
      <inertia ixx="0.000175" ixy="0.0" ixz="1e-05" iyy="0.000275" iyz="0.0" izz="0.000275"/>
    </inertial>
    <visual>
      <geometry>
        <mesh filename="package://soft_hand_description/meshes/phalanx.stl" scale=" .001 .001 .001"/>
      </geometry>
      <material name="SoftHand/DarkGrey"/>
    </visual>
    <collision>
      <geometry>
        <mesh filename="package://soft_hand_description/meshes/phalanx_collision.stl" scale=" .001 .001 .001"/>
      </geometry>
    </collision>
  </link>
  <!-- DISTAL PHALANGE -->
  <joint name="left_hand_little_outer_joint" type="revolute">
    <origin rpy="0 0 0" xyz="0.009 0 0"/>
    <parent link="left_hand_little_middle_link"/>
    <child link="left_hand_little_fake_link3"/>
    <axis xyz="0 -1 0"/>
    <limit effort="100" lower="0.0" upper="0.785398163397" velocity="100"/>
    <dynamics damping="0.0" friction="0.0"/>
    <mimic joint="left_hand_synergy_joint" multiplier="0.785398163397"/>
  </joint>
  <link name="left_hand_little_fake_link3">
    <inertial>
      <origin xyz="0 0 0"/>
      <mass value="0.2"/>
      <inertia ixx="0.02" ixy="0.0" ixz="0.0" iyy="0.02" iyz="0.0" izz="0.02"/>
    </inertial>
  </link>
  <joint name="left_hand_little_outer_joint_mimic" type="revolute">
    <origin rpy="0 0 0" xyz="0.013 0 0"/>
    <parent link="left_hand_little_fake_link3"/>
    <child link="left_hand_little_distal_link"/>
    <axis xyz="0 -1 0"/>
    <limit effort="100" lower="0.0" upper="0.785398163397" velocity="100"/>
    <dynamics damping="0.0" friction="0.0"/>
    <mimic joint="left_hand_synergy_joint" multiplier="0.785398163397"/>
  </joint>
  <link name="left_hand_little_distal_link">
    <inertial>
      <origin xyz="0.009849094 5.6e-07 0.000820286"/>
      <mass value="0.01"/>
      <inertia ixx="0.00035" ixy="0.0" ixz="2e-05" iyy="0.0008" iyz="0.0" izz="0.00076"/>
    </inertial>
    <visual>
      <geometry>
        <mesh filename="package://soft_hand_description/meshes/fingertip.stl" scale=" .001 .001 .001"/>
      </geometry>
      <material name="SoftHand/DarkGrey"/>
    </visual>
    <collision>
      <geometry>
        <mesh filename="package://soft_hand_description/meshes/fingertip_collision.stl" scale=" .001 .001 .001"/>
      </geometry>
    </collision>
  </link>
  <!-- work in progress -->
  <transmission name="left_hand_synergy_trans">
    <robotNamespace>left_hand</robotNamespace>
    <type>transmission_interface/SimpleTransmission</type>
    <joint name="left_hand_synergy_joint">
      <!-- <hardwareInterface>hardware_interface/PositionJointInterface</hardwareInterface> -->
      <hardwareInterface>hardware_interface/PositionJointInterface</hardwareInterface>
      <!-- <hardwareInterface>${Interface10}</hardwareInterface> -->
    </joint>
    <actuator name="left_hand_synergy_motor">
      <mechanicalReduction>1.0</mechanicalReduction>
    </actuator>
  </transmission>
  <transmission name="left_hand_joint_trans">
    <robotNamespace>left_hand</robotNamespace>
    <type>adaptive_transmission_interface/AdaptiveSynergyTransmission</type>
    <joint name="left_hand_thumb_abd_joint">
      <role>joint1</role>
      <offset>-0.0</offset>
      <mechanicalReduction>1.3</mechanicalReduction>
      <mechanicalElasticity>1.0</mechanicalElasticity>
      <!--hardwareInterface>hardware_interface/PositionJointInterface</hardwareInterface-->
      <hardwareInterface>hardware_interface/EffortJointInterface</hardwareInterface>
    </joint>
    <joint name="left_hand_thumb_inner_joint">
      <role>joint2</role>
      <offset>-0.0</offset>
      <mechanicalReduction>1.0</mechanicalReduction>
      <mechanicalElasticity>1.0</mechanicalElasticity>
      <!--hardwareInterface>hardware_interface/PositionJointInterface</hardwareInterface-->
      <hardwareInterface>hardware_interface/EffortJointInterface</hardwareInterface>
    </joint>
    <joint name="left_hand_thumb_outer_joint">
      <role>joint3</role>
      <offset>-0.0</offset>
      <mechanicalReduction>1.0</mechanicalReduction>
      <mechanicalElasticity>1.0</mechanicalElasticity>
      <!--hardwareInterface>hardware_interface/PositionJointInterface</hardwareInterface-->
      <hardwareInterface>hardware_interface/EffortJointInterface</hardwareInterface>
    </joint>
    <joint name="left_hand_index_abd_joint">
      <role>joint4</role>
      <offset>-0.0</offset>
      <mechanicalReduction>-0.2</mechanicalReduction>
      <mechanicalElasticity>1.0</mechanicalElasticity>
      <!--hardwareInterface>hardware_interface/PositionJointInterface</hardwareInterface-->
      <hardwareInterface>hardware_interface/EffortJointInterface</hardwareInterface>
    </joint>
    <joint name="left_hand_index_inner_joint">
      <role>joint5</role>
      <offset>-0.0</offset>
      <mechanicalReduction>1.0</mechanicalReduction>
      <mechanicalElasticity>1.0</mechanicalElasticity>
      <!--hardwareInterface>hardware_interface/PositionJointInterface</hardwareInterface-->
      <hardwareInterface>hardware_interface/EffortJointInterface</hardwareInterface>
    </joint>
    <joint name="left_hand_index_middle_joint">
      <role>joint6</role>
      <offset>-0.0</offset>
      <mechanicalReduction>1.0</mechanicalReduction>
      <mechanicalElasticity>1.0</mechanicalElasticity>
      <!--hardwareInterface>hardware_interface/PositionJointInterface</hardwareInterface-->
      <hardwareInterface>hardware_interface/EffortJointInterface</hardwareInterface>
    </joint>
    <joint name="left_hand_index_outer_joint">
      <role>joint7</role>
      <offset>-0.0</offset>
      <mechanicalReduction>1.0</mechanicalReduction>
      <mechanicalElasticity>1.0</mechanicalElasticity>
      <!--hardwareInterface>hardware_interface/PositionJointInterface</hardwareInterface-->
      <hardwareInterface>hardware_interface/EffortJointInterface</hardwareInterface>
    </joint>
    <joint name="left_hand_middle_abd_joint">
      <role>joint8</role>
      <offset>-0.0</offset>
      <mechanicalReduction>0.001</mechanicalReduction>
      <mechanicalElasticity>1.0</mechanicalElasticity>
      <!--hardwareInterface>hardware_interface/PositionJointInterface</hardwareInterface-->
      <hardwareInterface>hardware_interface/EffortJointInterface</hardwareInterface>
    </joint>
    <joint name="left_hand_middle_inner_joint">
      <role>joint9</role>
      <offset>-0.0</offset>
      <mechanicalReduction>1.0</mechanicalReduction>
      <mechanicalElasticity>1.0</mechanicalElasticity>
      <!--hardwareInterface>hardware_interface/PositionJointInterface</hardwareInterface-->
      <hardwareInterface>hardware_interface/EffortJointInterface</hardwareInterface>
    </joint>
    <joint name="left_hand_middle_middle_joint">
      <role>joint10</role>
      <offset>-0.0</offset>
      <mechanicalReduction>1.0</mechanicalReduction>
      <mechanicalElasticity>1.0</mechanicalElasticity>
      <!--hardwareInterface>hardware_interface/PositionJointInterface</hardwareInterface-->
      <hardwareInterface>hardware_interface/EffortJointInterface</hardwareInterface>
    </joint>
    <joint name="left_hand_middle_outer_joint">
      <role>joint11</role>
      <offset>-0.0</offset>
      <mechanicalReduction>1.0</mechanicalReduction>
      <mechanicalElasticity>1.0</mechanicalElasticity>
      <!--hardwareInterface>hardware_interface/PositionJointInterface</hardwareInterface-->
      <hardwareInterface>hardware_interface/EffortJointInterface</hardwareInterface>
    </joint>
    <joint name="left_hand_ring_abd_joint">
      <role>joint12</role>
      <offset>-0.0</offset>
      <mechanicalReduction>0.2</mechanicalReduction>
      <mechanicalElasticity>1.0</mechanicalElasticity>
      <!--hardwareInterface>hardware_interface/PositionJointInterface</hardwareInterface-->
      <hardwareInterface>hardware_interface/EffortJointInterface</hardwareInterface>
    </joint>
    <joint name="left_hand_ring_inner_joint">
      <role>joint13</role>
      <offset>-0.0</offset>
      <mechanicalReduction>1.0</mechanicalReduction>
      <mechanicalElasticity>1.0</mechanicalElasticity>
      <!--hardwareInterface>hardware_interface/PositionJointInterface</hardwareInterface-->
      <hardwareInterface>hardware_interface/EffortJointInterface</hardwareInterface>
    </joint>
    <joint name="left_hand_ring_middle_joint">
      <role>joint14</role>
      <offset>-0.0</offset>
      <mechanicalReduction>1.0</mechanicalReduction>
      <mechanicalElasticity>1.0</mechanicalElasticity>
      <!--hardwareInterface>hardware_interface/PositionJointInterface</hardwareInterface-->
      <hardwareInterface>hardware_interface/EffortJointInterface</hardwareInterface>
    </joint>
    <joint name="left_hand_ring_outer_joint">
      <role>joint15</role>
      <offset>-0.0</offset>
      <mechanicalReduction>1.0</mechanicalReduction>
      <mechanicalElasticity>1.0</mechanicalElasticity>
      <!--hardwareInterface>hardware_interface/PositionJointInterface</hardwareInterface-->
      <hardwareInterface>hardware_interface/EffortJointInterface</hardwareInterface>
    </joint>
    <joint name="left_hand_little_abd_joint">
      <role>joint16</role>
      <offset>-0.0</offset>
      <mechanicalReduction>0.4</mechanicalReduction>
      <mechanicalElasticity>1.0</mechanicalElasticity>
      <!--hardwareInterface>hardware_interface/PositionJointInterface</hardwareInterface-->
      <hardwareInterface>hardware_interface/EffortJointInterface</hardwareInterface>
    </joint>
    <joint name="left_hand_little_inner_joint">
      <role>joint17</role>
      <offset>-0.0</offset>
      <mechanicalReduction>1.0</mechanicalReduction>
      <mechanicalElasticity>1.0</mechanicalElasticity>
      <!--hardwareInterface>hardware_interface/PositionJointInterface</hardwareInterface-->
      <hardwareInterface>hardware_interface/EffortJointInterface</hardwareInterface>
    </joint>
    <joint name="left_hand_little_middle_joint">
      <role>joint18</role>
      <offset>-0.0</offset>
      <mechanicalReduction>1.0</mechanicalReduction>
      <mechanicalElasticity>1.0</mechanicalElasticity>
      <!--hardwareInterface>hardware_interface/PositionJointInterface</hardwareInterface-->
      <hardwareInterface>hardware_interface/EffortJointInterface</hardwareInterface>
    </joint>
    <joint name="left_hand_little_outer_joint">
      <role>joint19</role>
      <offset>-0.0</offset>
      <mechanicalReduction>1.0</mechanicalReduction>
      <mechanicalElasticity>1.0</mechanicalElasticity>
      <!--hardwareInterface>hardware_interface/PositionJointInterface</hardwareInterface-->
      <hardwareInterface>hardware_interface/EffortJointInterface</hardwareInterface>
    </joint>
    <!-- IMPORTANT: if you change the elasticity or reduction at the joints, this value must be calibrated again to
                          ensure that the joints don't go after the limits -->
    <!-- ToDO: autocalibration using the joint limits. When the synergy goes to 1, they must be at the upper limirt
                    and to 0, they must be at the lower limit -->
    <actuator name="left_hand_actuator">
      <role>actuator1</role>
      <mechanicalReduction>4.5</mechanicalReduction>
    </actuator>
  </transmission>
  <!-- work in progess -->
  <gazebo>
    <plugin filename="libgazebo_ros_soft_hand.so" name="gazebo_ros_soft_hand">
      <robotNamespace>left_hand</robotNamespace>
      <robotSimType>gazebo_ros_soft_hand/KinematicCtrlSoftHandHWSim</robotSimType>
    </plugin>
  </gazebo>
  <!-- LINKS -->
  <gazebo reference="left_hand_palm_link">
    <sensor name="left_hand_palm_link_contact" type="contact">
      <!-- the gazebo contact sensor -->
      <always_on>1</always_on>
      <update_rate>1000.0</update_rate>
      <contact>
        <collision>left_hand_palm_link_collision</collision>
        <topic>left_hand_palm_link_collision</topic>
      </contact>
      <!-- to publish a ros message with contact information -->
      <plugin filename="libgazebo_ros_bumper.so" name="left_hand_palm_link_gazebo_ros_bumper_plugin">
        <alwaysOn>true</alwaysOn>
        <frameName>left_hand_palm_link</frameName>
        <updateRate>100.0</updateRate>
        <bumperTopicName>/contacts/left_hand_palm_link</bumperTopicName>
      </plugin>
    </sensor>
    <gravity>true</gravity>
    <mu1>500.0</mu1>
    <mu2>500.0</mu2>
    <kp>1000000.0</kp>
    <kd>100.0</kd>
    <!-- <fdir1>string</fdir1> -->
    <!-- <dampingFactor>double</dampingFactor> -->
    <!-- <maxVel>double</maxVel> -->
    <!-- <minDepth>double</minDepth> -->
    <!-- <maxContacts>int</maxContacts> -->
  </gazebo>
  <gazebo reference="left_hand_thumb_knuckle_link">
    <sensor name="left_hand_thumb_knuckle_link_contact" type="contact">
      <!-- the gazebo contact sensor -->
      <always_on>1</always_on>
      <update_rate>1000.0</update_rate>
      <contact>
        <collision>left_hand_thumb_knuckle_link_collision</collision>
        <topic>left_hand_thumb_knuckle_link_collision</topic>
      </contact>
      <!-- to publish a ros message with contact information -->
      <plugin filename="libgazebo_ros_bumper.so" name="left_hand_thumb_knuckle_link_gazebo_ros_bumper_plugin">
        <alwaysOn>true</alwaysOn>
        <frameName>left_hand_thumb_knuckle_link</frameName>
        <updateRate>100.0</updateRate>
        <bumperTopicName>/contacts/left_hand_thumb_knuckle_link</bumperTopicName>
      </plugin>
    </sensor>
    <gravity>true</gravity>
    <mu1>500.0</mu1>
    <mu2>500.0</mu2>
    <kp>1000000.0</kp>
    <kd>100.0</kd>
    <!-- <fdir1>string</fdir1> -->
    <!-- <dampingFactor>double</dampingFactor> -->
    <!-- <maxVel>double</maxVel> -->
    <!-- <minDepth>double</minDepth> -->
    <!-- <maxContacts>int</maxContacts> -->
  </gazebo>
  <gazebo reference="left_hand_thumb_proximal_link">
    <sensor name="left_hand_thumb_proximal_link_contact" type="contact">
      <!-- the gazebo contact sensor -->
      <always_on>1</always_on>
      <update_rate>1000.0</update_rate>
      <contact>
        <collision>left_hand_thumb_proximal_link_collision</collision>
        <topic>left_hand_thumb_proximal_link_collision</topic>
      </contact>
      <!-- to publish a ros message with contact information -->
      <plugin filename="libgazebo_ros_bumper.so" name="left_hand_thumb_proximal_link_gazebo_ros_bumper_plugin">
        <alwaysOn>true</alwaysOn>
        <frameName>left_hand_thumb_proximal_link</frameName>
        <updateRate>100.0</updateRate>
        <bumperTopicName>/contacts/left_hand_thumb_proximal_link</bumperTopicName>
      </plugin>
    </sensor>
    <gravity>true</gravity>
    <mu1>500.0</mu1>
    <mu2>500.0</mu2>
    <kp>1000000.0</kp>
    <kd>100.0</kd>
    <!-- <fdir1>string</fdir1> -->
    <!-- <dampingFactor>double</dampingFactor> -->
    <!-- <maxVel>double</maxVel> -->
    <!-- <minDepth>double</minDepth> -->
    <!-- <maxContacts>int</maxContacts> -->
  </gazebo>
  <gazebo reference="left_hand_thumb_distal_link">
    <sensor name="left_hand_thumb_distal_link_contact" type="contact">
      <!-- the gazebo contact sensor -->
      <always_on>1</always_on>
      <update_rate>1000.0</update_rate>
      <contact>
        <collision>left_hand_thumb_distal_link_collision</collision>
        <topic>left_hand_thumb_distal_link_collision</topic>
      </contact>
      <!-- to publish a ros message with contact information -->
      <plugin filename="libgazebo_ros_bumper.so" name="left_hand_thumb_distal_link_gazebo_ros_bumper_plugin">
        <alwaysOn>true</alwaysOn>
        <frameName>left_hand_thumb_distal_link</frameName>
        <updateRate>100.0</updateRate>
        <bumperTopicName>/contacts/left_hand_thumb_distal_link</bumperTopicName>
      </plugin>
    </sensor>
    <gravity>true</gravity>
    <mu1>500.0</mu1>
    <mu2>500.0</mu2>
    <kp>1000000.0</kp>
    <kd>100.0</kd>
    <!-- <fdir1>string</fdir1> -->
    <!-- <dampingFactor>double</dampingFactor> -->
    <!-- <maxVel>double</maxVel> -->
    <!-- <minDepth>double</minDepth> -->
    <!-- <maxContacts>int</maxContacts> -->
  </gazebo>
  <gazebo reference="left_hand_index_knuckle_link">
    <sensor name="left_hand_index_knuckle_link_contact" type="contact">
      <!-- the gazebo contact sensor -->
      <always_on>1</always_on>
      <update_rate>1000.0</update_rate>
      <contact>
        <collision>left_hand_index_knuckle_link_collision</collision>
        <topic>left_hand_index_knuckle_link_collision</topic>
      </contact>
      <!-- to publish a ros message with contact information -->
      <plugin filename="libgazebo_ros_bumper.so" name="left_hand_index_knuckle_link_gazebo_ros_bumper_plugin">
        <alwaysOn>true</alwaysOn>
        <frameName>left_hand_index_knuckle_link</frameName>
        <updateRate>100.0</updateRate>
        <bumperTopicName>/contacts/left_hand_index_knuckle_link</bumperTopicName>
      </plugin>
    </sensor>
    <gravity>true</gravity>
    <mu1>500.0</mu1>
    <mu2>500.0</mu2>
    <kp>1000000.0</kp>
    <kd>100.0</kd>
    <!-- <fdir1>string</fdir1> -->
    <!-- <dampingFactor>double</dampingFactor> -->
    <!-- <maxVel>double</maxVel> -->
    <!-- <minDepth>double</minDepth> -->
    <!-- <maxContacts>int</maxContacts> -->
  </gazebo>
  <gazebo reference="left_hand_index_proximal_link">
    <sensor name="left_hand_index_proximal_link_contact" type="contact">
      <!-- the gazebo contact sensor -->
      <always_on>1</always_on>
      <update_rate>1000.0</update_rate>
      <contact>
        <collision>left_hand_index_proximal_link_collision</collision>
        <topic>left_hand_index_proximal_link_collision</topic>
      </contact>
      <!-- to publish a ros message with contact information -->
      <plugin filename="libgazebo_ros_bumper.so" name="left_hand_index_proximal_link_gazebo_ros_bumper_plugin">
        <alwaysOn>true</alwaysOn>
        <frameName>left_hand_index_proximal_link</frameName>
        <updateRate>100.0</updateRate>
        <bumperTopicName>/contacts/left_hand_index_proximal_link</bumperTopicName>
      </plugin>
    </sensor>
    <gravity>true</gravity>
    <mu1>500.0</mu1>
    <mu2>500.0</mu2>
    <kp>1000000.0</kp>
    <kd>100.0</kd>
    <!-- <fdir1>string</fdir1> -->
    <!-- <dampingFactor>double</dampingFactor> -->
    <!-- <maxVel>double</maxVel> -->
    <!-- <minDepth>double</minDepth> -->
    <!-- <maxContacts>int</maxContacts> -->
  </gazebo>
  <gazebo reference="left_hand_index_middle_link">
    <sensor name="left_hand_index_middle_link_contact" type="contact">
      <!-- the gazebo contact sensor -->
      <always_on>1</always_on>
      <update_rate>1000.0</update_rate>
      <contact>
        <collision>left_hand_index_middle_link_collision</collision>
        <topic>left_hand_index_middle_link_collision</topic>
      </contact>
      <!-- to publish a ros message with contact information -->
      <plugin filename="libgazebo_ros_bumper.so" name="left_hand_index_middle_link_gazebo_ros_bumper_plugin">
        <alwaysOn>true</alwaysOn>
        <frameName>left_hand_index_middle_link</frameName>
        <updateRate>100.0</updateRate>
        <bumperTopicName>/contacts/left_hand_index_middle_link</bumperTopicName>
      </plugin>
    </sensor>
    <gravity>true</gravity>
    <mu1>500.0</mu1>
    <mu2>500.0</mu2>
    <kp>1000000.0</kp>
    <kd>100.0</kd>
    <!-- <fdir1>string</fdir1> -->
    <!-- <dampingFactor>double</dampingFactor> -->
    <!-- <maxVel>double</maxVel> -->
    <!-- <minDepth>double</minDepth> -->
    <!-- <maxContacts>int</maxContacts> -->
  </gazebo>
  <gazebo reference="left_hand_index_distal_link">
    <sensor name="left_hand_index_distal_link_contact" type="contact">
      <!-- the gazebo contact sensor -->
      <always_on>1</always_on>
      <update_rate>1000.0</update_rate>
      <contact>
        <collision>left_hand_index_distal_link_collision</collision>
        <topic>left_hand_index_distal_link_collision</topic>
      </contact>
      <!-- to publish a ros message with contact information -->
      <plugin filename="libgazebo_ros_bumper.so" name="left_hand_index_distal_link_gazebo_ros_bumper_plugin">
        <alwaysOn>true</alwaysOn>
        <frameName>left_hand_index_distal_link</frameName>
        <updateRate>100.0</updateRate>
        <bumperTopicName>/contacts/left_hand_index_distal_link</bumperTopicName>
      </plugin>
    </sensor>
    <gravity>true</gravity>
    <mu1>500.0</mu1>
    <mu2>500.0</mu2>
    <kp>1000000.0</kp>
    <kd>100.0</kd>
    <!-- <fdir1>string</fdir1> -->
    <!-- <dampingFactor>double</dampingFactor> -->
    <!-- <maxVel>double</maxVel> -->
    <!-- <minDepth>double</minDepth> -->
    <!-- <maxContacts>int</maxContacts> -->
  </gazebo>
  <gazebo reference="left_hand_middle_knuckle_link">
    <sensor name="left_hand_middle_knuckle_link_contact" type="contact">
      <!-- the gazebo contact sensor -->
      <always_on>1</always_on>
      <update_rate>1000.0</update_rate>
      <contact>
        <collision>left_hand_middle_knuckle_link_collision</collision>
        <topic>left_hand_middle_knuckle_link_collision</topic>
      </contact>
      <!-- to publish a ros message with contact information -->
      <plugin filename="libgazebo_ros_bumper.so" name="left_hand_middle_knuckle_link_gazebo_ros_bumper_plugin">
        <alwaysOn>true</alwaysOn>
        <frameName>left_hand_middle_knuckle_link</frameName>
        <updateRate>100.0</updateRate>
        <bumperTopicName>/contacts/left_hand_middle_knuckle_link</bumperTopicName>
      </plugin>
    </sensor>
    <gravity>true</gravity>
    <mu1>500.0</mu1>
    <mu2>500.0</mu2>
    <kp>1000000.0</kp>
    <kd>100.0</kd>
    <!-- <fdir1>string</fdir1> -->
    <!-- <dampingFactor>double</dampingFactor> -->
    <!-- <maxVel>double</maxVel> -->
    <!-- <minDepth>double</minDepth> -->
    <!-- <maxContacts>int</maxContacts> -->
  </gazebo>
  <gazebo reference="left_hand_middle_proximal_link">
    <sensor name="left_hand_middle_proximal_link_contact" type="contact">
      <!-- the gazebo contact sensor -->
      <always_on>1</always_on>
      <update_rate>1000.0</update_rate>
      <contact>
        <collision>left_hand_middle_proximal_link_collision</collision>
        <topic>left_hand_middle_proximal_link_collision</topic>
      </contact>
      <!-- to publish a ros message with contact information -->
      <plugin filename="libgazebo_ros_bumper.so" name="left_hand_middle_proximal_link_gazebo_ros_bumper_plugin">
        <alwaysOn>true</alwaysOn>
        <frameName>left_hand_middle_proximal_link</frameName>
        <updateRate>100.0</updateRate>
        <bumperTopicName>/contacts/left_hand_middle_proximal_link</bumperTopicName>
      </plugin>
    </sensor>
    <gravity>true</gravity>
    <mu1>500.0</mu1>
    <mu2>500.0</mu2>
    <kp>1000000.0</kp>
    <kd>100.0</kd>
    <!-- <fdir1>string</fdir1> -->
    <!-- <dampingFactor>double</dampingFactor> -->
    <!-- <maxVel>double</maxVel> -->
    <!-- <minDepth>double</minDepth> -->
    <!-- <maxContacts>int</maxContacts> -->
  </gazebo>
  <gazebo reference="left_hand_middle_middle_link">
    <sensor name="left_hand_middle_middle_link_contact" type="contact">
      <!-- the gazebo contact sensor -->
      <always_on>1</always_on>
      <update_rate>1000.0</update_rate>
      <contact>
        <collision>left_hand_middle_middle_link_collision</collision>
        <topic>left_hand_middle_middle_link_collision</topic>
      </contact>
      <!-- to publish a ros message with contact information -->
      <plugin filename="libgazebo_ros_bumper.so" name="left_hand_middle_middle_link_gazebo_ros_bumper_plugin">
        <alwaysOn>true</alwaysOn>
        <frameName>left_hand_middle_middle_link</frameName>
        <updateRate>100.0</updateRate>
        <bumperTopicName>/contacts/left_hand_middle_middle_link</bumperTopicName>
      </plugin>
    </sensor>
    <gravity>true</gravity>
    <mu1>500.0</mu1>
    <mu2>500.0</mu2>
    <kp>1000000.0</kp>
    <kd>100.0</kd>
    <!-- <fdir1>string</fdir1> -->
    <!-- <dampingFactor>double</dampingFactor> -->
    <!-- <maxVel>double</maxVel> -->
    <!-- <minDepth>double</minDepth> -->
    <!-- <maxContacts>int</maxContacts> -->
  </gazebo>
  <gazebo reference="left_hand_middle_distal_link">
    <sensor name="left_hand_middle_distal_link_contact" type="contact">
      <!-- the gazebo contact sensor -->
      <always_on>1</always_on>
      <update_rate>1000.0</update_rate>
      <contact>
        <collision>left_hand_middle_distal_link_collision</collision>
        <topic>left_hand_middle_distal_link_collision</topic>
      </contact>
      <!-- to publish a ros message with contact information -->
      <plugin filename="libgazebo_ros_bumper.so" name="left_hand_middle_distal_link_gazebo_ros_bumper_plugin">
        <alwaysOn>true</alwaysOn>
        <frameName>left_hand_middle_distal_link</frameName>
        <updateRate>100.0</updateRate>
        <bumperTopicName>/contacts/left_hand_middle_distal_link</bumperTopicName>
      </plugin>
    </sensor>
    <gravity>true</gravity>
    <mu1>500.0</mu1>
    <mu2>500.0</mu2>
    <kp>1000000.0</kp>
    <kd>100.0</kd>
    <!-- <fdir1>string</fdir1> -->
    <!-- <dampingFactor>double</dampingFactor> -->
    <!-- <maxVel>double</maxVel> -->
    <!-- <minDepth>double</minDepth> -->
    <!-- <maxContacts>int</maxContacts> -->
  </gazebo>
  <gazebo reference="left_hand_ring_knuckle_link">
    <sensor name="left_hand_ring_knuckle_link_contact" type="contact">
      <!-- the gazebo contact sensor -->
      <always_on>1</always_on>
      <update_rate>1000.0</update_rate>
      <contact>
        <collision>left_hand_ring_knuckle_link_collision</collision>
        <topic>left_hand_ring_knuckle_link_collision</topic>
      </contact>
      <!-- to publish a ros message with contact information -->
      <plugin filename="libgazebo_ros_bumper.so" name="left_hand_ring_knuckle_link_gazebo_ros_bumper_plugin">
        <alwaysOn>true</alwaysOn>
        <frameName>left_hand_ring_knuckle_link</frameName>
        <updateRate>100.0</updateRate>
        <bumperTopicName>/contacts/left_hand_ring_knuckle_link</bumperTopicName>
      </plugin>
    </sensor>
    <gravity>true</gravity>
    <mu1>500.0</mu1>
    <mu2>500.0</mu2>
    <kp>1000000.0</kp>
    <kd>100.0</kd>
    <!-- <fdir1>string</fdir1> -->
    <!-- <dampingFactor>double</dampingFactor> -->
    <!-- <maxVel>double</maxVel> -->
    <!-- <minDepth>double</minDepth> -->
    <!-- <maxContacts>int</maxContacts> -->
  </gazebo>
  <gazebo reference="left_hand_ring_proximal_link">
    <sensor name="left_hand_ring_proximal_link_contact" type="contact">
      <!-- the gazebo contact sensor -->
      <always_on>1</always_on>
      <update_rate>1000.0</update_rate>
      <contact>
        <collision>left_hand_ring_proximal_link_collision</collision>
        <topic>left_hand_ring_proximal_link_collision</topic>
      </contact>
      <!-- to publish a ros message with contact information -->
      <plugin filename="libgazebo_ros_bumper.so" name="left_hand_ring_proximal_link_gazebo_ros_bumper_plugin">
        <alwaysOn>true</alwaysOn>
        <frameName>left_hand_ring_proximal_link</frameName>
        <updateRate>100.0</updateRate>
        <bumperTopicName>/contacts/left_hand_ring_proximal_link</bumperTopicName>
      </plugin>
    </sensor>
    <gravity>true</gravity>
    <mu1>500.0</mu1>
    <mu2>500.0</mu2>
    <kp>1000000.0</kp>
    <kd>100.0</kd>
    <!-- <fdir1>string</fdir1> -->
    <!-- <dampingFactor>double</dampingFactor> -->
    <!-- <maxVel>double</maxVel> -->
    <!-- <minDepth>double</minDepth> -->
    <!-- <maxContacts>int</maxContacts> -->
  </gazebo>
  <gazebo reference="left_hand_ring_middle_link">
    <sensor name="left_hand_ring_middle_link_contact" type="contact">
      <!-- the gazebo contact sensor -->
      <always_on>1</always_on>
      <update_rate>1000.0</update_rate>
      <contact>
        <collision>left_hand_ring_middle_link_collision</collision>
        <topic>left_hand_ring_middle_link_collision</topic>
      </contact>
      <!-- to publish a ros message with contact information -->
      <plugin filename="libgazebo_ros_bumper.so" name="left_hand_ring_middle_link_gazebo_ros_bumper_plugin">
        <alwaysOn>true</alwaysOn>
        <frameName>left_hand_ring_middle_link</frameName>
        <updateRate>100.0</updateRate>
        <bumperTopicName>/contacts/left_hand_ring_middle_link</bumperTopicName>
      </plugin>
    </sensor>
    <gravity>true</gravity>
    <mu1>500.0</mu1>
    <mu2>500.0</mu2>
    <kp>1000000.0</kp>
    <kd>100.0</kd>
    <!-- <fdir1>string</fdir1> -->
    <!-- <dampingFactor>double</dampingFactor> -->
    <!-- <maxVel>double</maxVel> -->
    <!-- <minDepth>double</minDepth> -->
    <!-- <maxContacts>int</maxContacts> -->
  </gazebo>
  <gazebo reference="left_hand_ring_distal_link">
    <sensor name="left_hand_ring_distal_link_contact" type="contact">
      <!-- the gazebo contact sensor -->
      <always_on>1</always_on>
      <update_rate>1000.0</update_rate>
      <contact>
        <collision>left_hand_ring_distal_link_collision</collision>
        <topic>left_hand_ring_distal_link_collision</topic>
      </contact>
      <!-- to publish a ros message with contact information -->
      <plugin filename="libgazebo_ros_bumper.so" name="left_hand_ring_distal_link_gazebo_ros_bumper_plugin">
        <alwaysOn>true</alwaysOn>
        <frameName>left_hand_ring_distal_link</frameName>
        <updateRate>100.0</updateRate>
        <bumperTopicName>/contacts/left_hand_ring_distal_link</bumperTopicName>
      </plugin>
    </sensor>
    <gravity>true</gravity>
    <mu1>500.0</mu1>
    <mu2>500.0</mu2>
    <kp>1000000.0</kp>
    <kd>100.0</kd>
    <!-- <fdir1>string</fdir1> -->
    <!-- <dampingFactor>double</dampingFactor> -->
    <!-- <maxVel>double</maxVel> -->
    <!-- <minDepth>double</minDepth> -->
    <!-- <maxContacts>int</maxContacts> -->
  </gazebo>
  <gazebo reference="left_hand_little_knuckle_link">
    <sensor name="left_hand_little_knuckle_link_contact" type="contact">
      <!-- the gazebo contact sensor -->
      <always_on>1</always_on>
      <update_rate>1000.0</update_rate>
      <contact>
        <collision>left_hand_little_knuckle_link_collision</collision>
        <topic>left_hand_little_knuckle_link_collision</topic>
      </contact>
      <!-- to publish a ros message with contact information -->
      <plugin filename="libgazebo_ros_bumper.so" name="left_hand_little_knuckle_link_gazebo_ros_bumper_plugin">
        <alwaysOn>true</alwaysOn>
        <frameName>left_hand_little_knuckle_link</frameName>
        <updateRate>100.0</updateRate>
        <bumperTopicName>/contacts/left_hand_little_knuckle_link</bumperTopicName>
      </plugin>
    </sensor>
    <gravity>true</gravity>
    <mu1>500.0</mu1>
    <mu2>500.0</mu2>
    <kp>1000000.0</kp>
    <kd>100.0</kd>
    <!-- <fdir1>string</fdir1> -->
    <!-- <dampingFactor>double</dampingFactor> -->
    <!-- <maxVel>double</maxVel> -->
    <!-- <minDepth>double</minDepth> -->
    <!-- <maxContacts>int</maxContacts> -->
  </gazebo>
  <gazebo reference="left_hand_little_proximal_link">
    <sensor name="left_hand_little_proximal_link_contact" type="contact">
      <!-- the gazebo contact sensor -->
      <always_on>1</always_on>
      <update_rate>1000.0</update_rate>
      <contact>
        <collision>left_hand_little_proximal_link_collision</collision>
        <topic>left_hand_little_proximal_link_collision</topic>
      </contact>
      <!-- to publish a ros message with contact information -->
      <plugin filename="libgazebo_ros_bumper.so" name="left_hand_little_proximal_link_gazebo_ros_bumper_plugin">
        <alwaysOn>true</alwaysOn>
        <frameName>left_hand_little_proximal_link</frameName>
        <updateRate>100.0</updateRate>
        <bumperTopicName>/contacts/left_hand_little_proximal_link</bumperTopicName>
      </plugin>
    </sensor>
    <gravity>true</gravity>
    <mu1>500.0</mu1>
    <mu2>500.0</mu2>
    <kp>1000000.0</kp>
    <kd>100.0</kd>
    <!-- <fdir1>string</fdir1> -->
    <!-- <dampingFactor>double</dampingFactor> -->
    <!-- <maxVel>double</maxVel> -->
    <!-- <minDepth>double</minDepth> -->
    <!-- <maxContacts>int</maxContacts> -->
  </gazebo>
  <gazebo reference="left_hand_little_middle_link">
    <sensor name="left_hand_little_middle_link_contact" type="contact">
      <!-- the gazebo contact sensor -->
      <always_on>1</always_on>
      <update_rate>1000.0</update_rate>
      <contact>
        <collision>left_hand_little_middle_link_collision</collision>
        <topic>left_hand_little_middle_link_collision</topic>
      </contact>
      <!-- to publish a ros message with contact information -->
      <plugin filename="libgazebo_ros_bumper.so" name="left_hand_little_middle_link_gazebo_ros_bumper_plugin">
        <alwaysOn>true</alwaysOn>
        <frameName>left_hand_little_middle_link</frameName>
        <updateRate>100.0</updateRate>
        <bumperTopicName>/contacts/left_hand_little_middle_link</bumperTopicName>
      </plugin>
    </sensor>
    <gravity>true</gravity>
    <mu1>500.0</mu1>
    <mu2>500.0</mu2>
    <kp>1000000.0</kp>
    <kd>100.0</kd>
    <!-- <fdir1>string</fdir1> -->
    <!-- <dampingFactor>double</dampingFactor> -->
    <!-- <maxVel>double</maxVel> -->
    <!-- <minDepth>double</minDepth> -->
    <!-- <maxContacts>int</maxContacts> -->
  </gazebo>
  <gazebo reference="left_hand_little_distal_link">
    <sensor name="left_hand_little_distal_link_contact" type="contact">
      <!-- the gazebo contact sensor -->
      <always_on>1</always_on>
      <update_rate>1000.0</update_rate>
      <contact>
        <collision>left_hand_little_distal_link_collision</collision>
        <topic>left_hand_little_distal_link_collision</topic>
      </contact>
      <!-- to publish a ros message with contact information -->
      <plugin filename="libgazebo_ros_bumper.so" name="left_hand_little_distal_link_gazebo_ros_bumper_plugin">
        <alwaysOn>true</alwaysOn>
        <frameName>left_hand_little_distal_link</frameName>
        <updateRate>100.0</updateRate>
        <bumperTopicName>/contacts/left_hand_little_distal_link</bumperTopicName>
      </plugin>
    </sensor>
    <gravity>true</gravity>
    <mu1>500.0</mu1>
    <mu2>500.0</mu2>
    <kp>1000000.0</kp>
    <kd>100.0</kd>
    <!-- <fdir1>string</fdir1> -->
    <!-- <dampingFactor>double</dampingFactor> -->
    <!-- <maxVel>double</maxVel> -->
    <!-- <minDepth>double</minDepth> -->
    <!-- <maxContacts>int</maxContacts> -->
  </gazebo>
  <!-- JOINTS -->
  <gazebo reference="left_hand_thumb_abd_joint">
    <provideFeedback>True</provideFeedback>
    <!--
		<kp> </kp>
		<kd> 1.0 </kd>
		<stopCfm> </stopCfm>
		<stopErp> </stopErp>
		<cfmDamping> </cfmDamping>
		<fudgeFactor> </fudgeFactor>
		-->
  </gazebo>
  <gazebo reference="left_hand_thumb_inner_joint">
    <provideFeedback>True</provideFeedback>
    <!--
		<kp> </kp>
		<kd> 1.0 </kd>
		<stopCfm> </stopCfm>
		<stopErp> </stopErp>
		<cfmDamping> </cfmDamping>
		<fudgeFactor> </fudgeFactor>
		-->
  </gazebo>
  <gazebo reference="left_hand_thumb_outer_joint">
    <provideFeedback>True</provideFeedback>
    <!--
		<kp> </kp>
		<kd> 1.0 </kd>
		<stopCfm> </stopCfm>
		<stopErp> </stopErp>
		<cfmDamping> </cfmDamping>
		<fudgeFactor> </fudgeFactor>
		-->
  </gazebo>
  <gazebo reference="left_hand_index_abd_joint">
    <provideFeedback>True</provideFeedback>
    <!--
		<kp> </kp>
		<kd> 1.0 </kd>
		<stopCfm> </stopCfm>
		<stopErp> </stopErp>
		<cfmDamping> </cfmDamping>
		<fudgeFactor> </fudgeFactor>
		-->
  </gazebo>
  <gazebo reference="left_hand_index_inner_joint">
    <provideFeedback>True</provideFeedback>
    <!--
		<kp> </kp>
		<kd> 1.0 </kd>
		<stopCfm> </stopCfm>
		<stopErp> </stopErp>
		<cfmDamping> </cfmDamping>
		<fudgeFactor> </fudgeFactor>
		-->
  </gazebo>
  <gazebo reference="left_hand_index_middle_joint">
    <provideFeedback>True</provideFeedback>
    <!--
		<kp> </kp>
		<kd> 1.0 </kd>
		<stopCfm> </stopCfm>
		<stopErp> </stopErp>
		<cfmDamping> </cfmDamping>
		<fudgeFactor> </fudgeFactor>
		-->
  </gazebo>
  <gazebo reference="left_hand_index_outer_joint">
    <provideFeedback>True</provideFeedback>
    <!--
		<kp> </kp>
		<kd> 1.0 </kd>
		<stopCfm> </stopCfm>
		<stopErp> </stopErp>
		<cfmDamping> </cfmDamping>
		<fudgeFactor> </fudgeFactor>
		-->
  </gazebo>
  <gazebo reference="left_hand_middle_abd_joint">
    <provideFeedback>True</provideFeedback>
    <!--
		<kp> </kp>
		<kd> 1.0 </kd>
		<stopCfm> </stopCfm>
		<stopErp> </stopErp>
		<cfmDamping> </cfmDamping>
		<fudgeFactor> </fudgeFactor>
		-->
  </gazebo>
  <gazebo reference="left_hand_middle_inner_joint">
    <provideFeedback>True</provideFeedback>
    <!--
		<kp> </kp>
		<kd> 1.0 </kd>
		<stopCfm> </stopCfm>
		<stopErp> </stopErp>
		<cfmDamping> </cfmDamping>
		<fudgeFactor> </fudgeFactor>
		-->
  </gazebo>
  <gazebo reference="left_hand_middle_middle_joint">
    <provideFeedback>True</provideFeedback>
    <!--
		<kp> </kp>
		<kd> 1.0 </kd>
		<stopCfm> </stopCfm>
		<stopErp> </stopErp>
		<cfmDamping> </cfmDamping>
		<fudgeFactor> </fudgeFactor>
		-->
  </gazebo>
  <gazebo reference="left_hand_middle_outer_joint">
    <provideFeedback>True</provideFeedback>
    <!--
		<kp> </kp>
		<kd> 1.0 </kd>
		<stopCfm> </stopCfm>
		<stopErp> </stopErp>
		<cfmDamping> </cfmDamping>
		<fudgeFactor> </fudgeFactor>
		-->
  </gazebo>
  <gazebo reference="left_hand_ring_abd_joint">
    <provideFeedback>True</provideFeedback>
    <!--
		<kp> </kp>
		<kd> 1.0 </kd>
		<stopCfm> </stopCfm>
		<stopErp> </stopErp>
		<cfmDamping> </cfmDamping>
		<fudgeFactor> </fudgeFactor>
		-->
  </gazebo>
  <gazebo reference="left_hand_ring_inner_joint">
    <provideFeedback>True</provideFeedback>
    <!--
		<kp> </kp>
		<kd> 1.0 </kd>
		<stopCfm> </stopCfm>
		<stopErp> </stopErp>
		<cfmDamping> </cfmDamping>
		<fudgeFactor> </fudgeFactor>
		-->
  </gazebo>
  <gazebo reference="left_hand_ring_middle_joint">
    <provideFeedback>True</provideFeedback>
    <!--
		<kp> </kp>
		<kd> 1.0 </kd>
		<stopCfm> </stopCfm>
		<stopErp> </stopErp>
		<cfmDamping> </cfmDamping>
		<fudgeFactor> </fudgeFactor>
		-->
  </gazebo>
  <gazebo reference="left_hand_ring_outer_joint">
    <provideFeedback>True</provideFeedback>
    <!--
		<kp> </kp>
		<kd> 1.0 </kd>
		<stopCfm> </stopCfm>
		<stopErp> </stopErp>
		<cfmDamping> </cfmDamping>
		<fudgeFactor> </fudgeFactor>
		-->
  </gazebo>
  <gazebo reference="left_hand_little_abd_joint">
    <provideFeedback>True</provideFeedback>
    <!--
		<kp> </kp>
		<kd> 1.0 </kd>
		<stopCfm> </stopCfm>
		<stopErp> </stopErp>
		<cfmDamping> </cfmDamping>
		<fudgeFactor> </fudgeFactor>
		-->
  </gazebo>
  <gazebo reference="left_hand_little_inner_joint">
    <provideFeedback>True</provideFeedback>
    <!--
		<kp> </kp>
		<kd> 1.0 </kd>
		<stopCfm> </stopCfm>
		<stopErp> </stopErp>
		<cfmDamping> </cfmDamping>
		<fudgeFactor> </fudgeFactor>
		-->
  </gazebo>
  <gazebo reference="left_hand_little_middle_joint">
    <provideFeedback>True</provideFeedback>
    <!--
		<kp> </kp>
		<kd> 1.0 </kd>
		<stopCfm> </stopCfm>
		<stopErp> </stopErp>
		<cfmDamping> </cfmDamping>
		<fudgeFactor> </fudgeFactor>
		-->
  </gazebo>
  <gazebo reference="left_hand_little_outer_joint">
    <provideFeedback>True</provideFeedback>
    <!--
		<kp> </kp>
		<kd> 1.0 </kd>
		<stopCfm> </stopCfm>
		<stopErp> </stopErp>
		<cfmDamping> </cfmDamping>
		<fudgeFactor> </fudgeFactor>
		-->
  </gazebo>
  <!-- mimic joints -->
  <gazebo reference="left_hand_thumb_inner_joint_mimic">
    <provideFeedback>True</provideFeedback>
    <!--
		<kp> </kp>
		<kd> 1.0 </kd>
		<stopCfm> </stopCfm>
		<stopErp> </stopErp>
		<cfmDamping> </cfmDamping>
		<fudgeFactor> </fudgeFactor>
		-->
  </gazebo>
  <gazebo reference="left_hand_thumb_outer_joint_mimic">
    <provideFeedback>True</provideFeedback>
    <!--
		<kp> </kp>
		<kd> 1.0 </kd>
		<stopCfm> </stopCfm>
		<stopErp> </stopErp>
		<cfmDamping> </cfmDamping>
		<fudgeFactor> </fudgeFactor>
		-->
  </gazebo>
  <gazebo reference="left_hand_index_inner_joint_mimic">
    <provideFeedback>True</provideFeedback>
    <!--
		<kp> </kp>
		<kd> 1.0 </kd>
		<stopCfm> </stopCfm>
		<stopErp> </stopErp>
		<cfmDamping> </cfmDamping>
		<fudgeFactor> </fudgeFactor>
		-->
  </gazebo>
  <gazebo reference="left_hand_index_middle_joint_mimic">
    <provideFeedback>True</provideFeedback>
    <!--
		<kp> </kp>
		<kd> 1.0 </kd>
		<stopCfm> </stopCfm>
		<stopErp> </stopErp>
		<cfmDamping> </cfmDamping>
		<fudgeFactor> </fudgeFactor>
		-->
  </gazebo>
  <gazebo reference="left_hand_index_outer_joint_mimic">
    <provideFeedback>True</provideFeedback>
    <!--
		<kp> </kp>
		<kd> 1.0 </kd>
		<stopCfm> </stopCfm>
		<stopErp> </stopErp>
		<cfmDamping> </cfmDamping>
		<fudgeFactor> </fudgeFactor>
		-->
  </gazebo>
  <gazebo reference="left_hand_middle_inner_joint_mimic">
    <provideFeedback>True</provideFeedback>
    <!--
		<kp> </kp>
		<kd> 1.0 </kd>
		<stopCfm> </stopCfm>
		<stopErp> </stopErp>
		<cfmDamping> </cfmDamping>
		<fudgeFactor> </fudgeFactor>
		-->
  </gazebo>
  <gazebo reference="left_hand_middle_middle_joint_mimic">
    <provideFeedback>True</provideFeedback>
    <!--
		<kp> </kp>
		<kd> 1.0 </kd>
		<stopCfm> </stopCfm>
		<stopErp> </stopErp>
		<cfmDamping> </cfmDamping>
		<fudgeFactor> </fudgeFactor>
		-->
  </gazebo>
  <gazebo reference="left_hand_middle_outer_joint_mimic">
    <provideFeedback>True</provideFeedback>
    <!--
		<kp> </kp>
		<kd> 1.0 </kd>
		<stopCfm> </stopCfm>
		<stopErp> </stopErp>
		<cfmDamping> </cfmDamping>
		<fudgeFactor> </fudgeFactor>
		-->
  </gazebo>
  <gazebo reference="left_hand_ring_inner_joint_mimic">
    <provideFeedback>True</provideFeedback>
    <!--
		<kp> </kp>
		<kd> 1.0 </kd>
		<stopCfm> </stopCfm>
		<stopErp> </stopErp>
		<cfmDamping> </cfmDamping>
		<fudgeFactor> </fudgeFactor>
		-->
  </gazebo>
  <gazebo reference="left_hand_ring_middle_joint_mimic">
    <provideFeedback>True</provideFeedback>
    <!--
		<kp> </kp>
		<kd> 1.0 </kd>
		<stopCfm> </stopCfm>
		<stopErp> </stopErp>
		<cfmDamping> </cfmDamping>
		<fudgeFactor> </fudgeFactor>
		-->
  </gazebo>
  <gazebo reference="left_hand_ring_outer_joint_mimic">
    <provideFeedback>True</provideFeedback>
    <!--
		<kp> </kp>
		<kd> 1.0 </kd>
		<stopCfm> </stopCfm>
		<stopErp> </stopErp>
		<cfmDamping> </cfmDamping>
		<fudgeFactor> </fudgeFactor>
		-->
  </gazebo>
  <gazebo reference="left_hand_little_inner_joint_mimic">
    <provideFeedback>True</provideFeedback>
    <!--
		<kp> </kp>
		<kd> 1.0 </kd>
		<stopCfm> </stopCfm>
		<stopErp> </stopErp>
		<cfmDamping> </cfmDamping>
		<fudgeFactor> </fudgeFactor>
		-->
  </gazebo>
  <gazebo reference="left_hand_little_middle_joint_mimic">
    <provideFeedback>True</provideFeedback>
    <!--
		<kp> </kp>
		<kd> 1.0 </kd>
		<stopCfm> </stopCfm>
		<stopErp> </stopErp>
		<cfmDamping> </cfmDamping>
		<fudgeFactor> </fudgeFactor>
		-->
  </gazebo>
  <gazebo reference="left_hand_little_outer_joint_mimic">
    <provideFeedback>True</provideFeedback>
    <!--
		<kp> </kp>
		<kd> 1.0 </kd>
		<stopCfm> </stopCfm>
		<stopErp> </stopErp>
		<cfmDamping> </cfmDamping>
		<fudgeFactor> </fudgeFactor>
		-->
  </gazebo>
  <!-- RIGHT ARM -->
  <!-- <xacro:kuka_lwr name="right_arm" parent="world">
		<origin xyz="0 -0.12853 0.20722" rpy="0 ${75 * M_PI / 180} ${-90 * M_PI / 180}"/>
  </xacro:kuka_lwr> -->
  <!-- 0 -0.12853 0.20722-->
  <!-- RIGHT DEPTH SENSOR -->
  <!-- <xacro:depth_sensor name="right" parent="right_arm_7_link">
		<origin xyz="-0.0751738 -0.00186555 0.08051474" rpy="3.131270940071478 -0.08173348350733739 -3.1183375574826124"/>
  </xacro:depth_sensor> -->
  <!-- RIGHT SOFTHAND -->
  <!-- <xacro:soft_hand parent="right_arm_7_link" name="right_hand" left="false" withAdaptiveTransmission="true" useMimicTag="$(arg use_mimic_tag)">
    <origin xyz="0 0 0.072" rpy="0 0 ${-135 * M_PI / 180}"/>
  </xacro:soft_hand> -->
  <!--055-->
  <!-- HEAD -->
  <!-- <xacro:kit_head name="head" parent="world">
    <origin xyz="0.0 0.0 0.61" rpy="0.0 0.0 0.0"/> 
  </xacro:kit_head> -->
  <!-- 0.58 -->
</robot>

