<?xml version="1.0" ?>

<!-- =================================================================================== -->
<!-- |    This document was autogenerated by xacro                                     | -->
<!-- |    from kinova/kinova-ros/kinova_description/urdf/j2n6s300_standalone.xacro     | -->
<!-- |    EDITING THIS FILE BY HAND IS NOT RECOMMENDED                                 | -->
<!-- =================================================================================== -->
<!-- j2n6s300 refers to jaco v2 6DOF non-spherical 3fingers -->

<robot name="j2n6s300" xmlns:xacro="http://ros.org/wiki/xacro">

  <link name="j2n6s300_link_base">
    <visual>
      <geometry>
        <mesh filename="meshes/base.dae"/>
      </geometry>
      <material name="carbon_fiber">
        <color rgba="0.2 0.2 0.2 1"/>
      </material>
    </visual>
    <collision>
      <geometry>
        <mesh filename="meshes/base.dae"/>
      </geometry>
    </collision>
    <inertial>
      <mass value="0.46784"/>
      <origin rpy="0 0 0" xyz="0 0 0.1255"/>
      <inertia ixx="0.000951270861568" ixy="0" ixz="0" iyy="0.000951270861568" iyz="0" izz="0.000374272"/>
    </inertial>
  </link>

  <link name="j2n6s300_link_1">
    <visual>
      <geometry>
        <mesh filename="meshes/shoulder.dae"/>
      </geometry>
      <material name="carbon_fiber"/>
    </visual>
    <collision>
      <geometry>
        <mesh filename="meshes/shoulder.dae"/>
      </geometry>
    </collision>
    <inertial>
      <mass value="0.7477"/>
      <origin xyz="0 -0.002 -0.0605"/>
      <inertia ixx="0.00152031725204" ixy="0" ixz="0" iyy="0.00152031725204" iyz="0" izz="0.00059816"/>
    </inertial>
  </link>

  <joint name="j2n6s300_joint_1" type="continuous">
    <parent link="j2n6s300_link_base"/>
    <child link="j2n6s300_link_1"/>
    <axis xyz="0 0 1"/>
    <limit effort="2000" lower="-6.28318530718" upper="6.28318530718" velocity="1"/>
    <origin rpy="0 3.14159265359 0" xyz="0 0 0.15675"/>
    <dynamics damping="0.0" friction="0.0"/>
  </joint>

  <link name="j2n6s300_link_2">
    <visual>
      <geometry>
        <mesh filename="meshes/arm.dae"/>
      </geometry>
      <material name="carbon_fiber"/>
    </visual>
    <collision>
      <geometry>
        <mesh filename="meshes/arm.dae"/>
      </geometry>
    </collision>
    <inertial>
      <mass value="0.99"/>
      <origin xyz="0 -0.2065 -0.01"/>
      <inertia ixx="0.010502207991" ixy="0" ixz="0" iyy="0.000792" iyz="0" izz="0.010502207991"/>
    </inertial>
  </link>

  <joint name="j2n6s300_joint_2" type="revolute">
    <parent link="j2n6s300_link_1"/>
    <child link="j2n6s300_link_2"/>
    <axis xyz="0 0 1"/>
    <limit effort="2000" lower="0.523598775598" upper="5.75958653158" velocity="1"/>
    <origin rpy="-1.57079632679 0 3.14159265359" xyz="0 0.0016 -0.11875"/>
    <dynamics damping="0.0" friction="0.0"/>
  </joint>

  <link name="j2n6s300_link_3">
    <visual>
      <geometry>
        <mesh filename="meshes/forearm.dae"/>
      </geometry>
      <material name="carbon_fiber"/>
    </visual>
    <collision>
      <geometry>
        <mesh filename="meshes/forearm.dae"/>
      </geometry>
    </collision>
    <inertial>
      <mass value="0.6763"/>
      <origin xyz="0 0.081 -0.0086"/>
      <inertia ixx="0.00142022431908" ixy="0" ixz="0" iyy="0.000304335" iyz="0" izz="0.00142022431908"/>
    </inertial>
  </link>

  <joint name="j2n6s300_joint_3" type="revolute">
    <parent link="j2n6s300_link_2"/>
    <child link="j2n6s300_link_3"/>  <axis xyz="0 0 1"/>
    <limit effort="2000" lower="0.523598775598" upper="5.75958653158" velocity="1"/>
    <origin rpy="0 3.14159265359 0" xyz="0 -0.410 0"/>
    <dynamics damping="0.0" friction="0.0"/>
  </joint>

  <link name="j2n6s300_link_4">
    <visual>
      <geometry>
        <mesh filename="meshes/wrist.dae"/>
      </geometry>
      <material name="carbon_fiber"/>
    </visual>
    <collision>
      <geometry>
        <mesh filename="meshes/wrist.dae"/>
      </geometry>
    </collision>
    <inertial>
      <mass value="0.426367"/>
      <origin xyz="0 -0.037 -0.0642"/>
      <inertia ixx="7.73496906e-05" ixy="0" ixz="0" iyy="7.73496906e-05" iyz="0" izz="0.0001428"/>
    </inertial>
  </link>

  <joint name="j2n6s300_joint_4" type="continuous">
    <parent link="j2n6s300_link_3"/>
    <child link="j2n6s300_link_4"/>
    <axis xyz="0 0 1"/>
    <limit effort="2000" lower="-6.28318530718" upper="6.28318530718" velocity="1"/>
    <origin rpy="-1.57079632679 0 3.14159265359" xyz="0 0.2073 -0.0114"/>
    <dynamics damping="0.0" friction="0.0"/>
  </joint>

  <link name="j2n6s300_link_5">
    <visual>
      <geometry>
        <mesh filename="meshes/wrist.dae"/>
      </geometry>
      <material name="carbon_fiber"/>
    </visual>
    <collision>
      <geometry>
        <mesh filename="meshes/wrist.dae"/>
      </geometry>
    </collision>
    <inertial>
      <mass value="0.426367"/>
      <origin xyz="0 -0.037 -0.0642"/>
      <inertia ixx="7.73496906e-05" ixy="0" ixz="0" iyy="7.73496906e-05" iyz="0" izz="0.0001428"/>
    </inertial>
  </link>

  <joint name="j2n6s300_joint_5" type="continuous">
    <parent link="j2n6s300_link_4"/>
    <child link="j2n6s300_link_5"/>
    <axis xyz="0 0 1"/>
    <limit effort="2000" lower="-6.28318530718" upper="6.28318530718" velocity="1"/>
    <origin rpy="1.0471975512 0 3.14159265359" xyz="0 -0.03703 -0.06414"/>
    <dynamics damping="0.0" friction="0.0"/>
  </joint>

  <link name="j2n6s300_link_6">
    <contact>
      <lateral_friction value="0.8"/>
      <spinning_friction value="0.0"/>
      <contact_cfm value="0.1"/>
      <contact_erp value="0.2"/>
    </contact>
    <visual>
      <geometry>
        <mesh filename="meshes/hand_3finger.dae"/>
      </geometry>
      <material name="carbon_fiber"/>
    </visual>
    <collision>
      <geometry>
        <mesh filename="meshes/hand_3finger.dae"/>
      </geometry>
    </collision>
    <inertial>
      <mass value="0.99"/>
      <origin xyz="0 0 -0.06"/>
      <inertia ixx="0.0003453236187" ixy="0" ixz="0" iyy="0.0003453236187" iyz="0" izz="0.0005816"/>
    </inertial>
  </link>

  <!-- virtual ft_sensor -->
  <link name="j2n6s300_ft_sensor">
    <inertial>
      <origin rpy="0 0 0" xyz="0 0 0"/>
      <mass value="0.0001"/>
      <inertia ixx="1e-08" ixy="0" ixz="0" iyy="1e-08" iyz="0" izz="1e-08"/>
    </inertial>
  </link>

  <joint name="j2n6s300_joint_ft_sensor" type="fixed">
    <parent link="j2n6s300_link_5"/>
    <child link="j2n6s300_ft_sensor"/>
    <axis xyz="0 0 0"/>
    <origin rpy="0 0 0" xyz="0 0 0"/>
  </joint>

  <joint name="j2n6s300_joint_6" type="continuous">
    <!-- <parent link="j2n6s300_link_5"/> -->
    <parent link="j2n6s300_ft_sensor"/>
    <child link="j2n6s300_link_6"/>
    <axis xyz="0 0 1"/>
    <limit effort="2000" lower="-6.28318530718" upper="6.28318530718" velocity="1"/>
    <origin rpy="1.0471975512 0 3.14159265359" xyz="0 -0.03703 -0.06414"/>
    <dynamics damping="0.0" friction="0.0"/>
  </joint>

  <link name="j2n6s300_end_effector">
    <inertial>
      <origin rpy="0 0 0" xyz="0 0 0"/>
      <mass value="0.0001"/>
      <inertia ixx="1e-08" ixy="0" ixz="0" iyy="1e-08" iyz="0" izz="1e-08"/>
    </inertial>
  </link>

  <joint name="j2n6s300_joint_end_effector" type="fixed">
    <parent link="j2n6s300_link_6"/>
    <child link="j2n6s300_end_effector"/>
    <axis xyz="0 0 0"/>
    <limit effort="2000" lower="0" upper="0" velocity="1"/>
    <origin rpy="3.14159265359 0 0" xyz="0 0 -0.1600"/>
  </joint>

  <link name="j2n6s300_link_finger_1">
    <contact>
      <lateral_friction value="0.8"/>
      <spinning_friction value="0.1"/>
      <contact_cfm value="0.1"/>
      <contact_erp value="0.2"/>
    </contact>
    <visual>
      <geometry>
        <mesh filename="meshes/finger_proximal.dae"/>
      </geometry>
      <material name="finger_gray">
        <color rgba="0.8 0.8 0.8 1"/>
      </material>
    </visual>
    <collision>
      <geometry>
        <mesh filename="meshes/finger_proximal.dae"/>
      </geometry>
    </collision>
    <inertial>
      <mass value="0.01"/>
      <origin xyz="0.022 0 0"/>
      <inertia ixx="7.8999684e-07" ixy="0" ixz="0" iyy="7.8999684e-07" iyz="0" izz="8e-08"/>
    </inertial>
  </link>

  <joint name="j2n6s300_joint_finger_1" type="revolute">
    <parent link="j2n6s300_link_6"/>
    <child link="j2n6s300_link_finger_1"/>
    <axis xyz="0 0 1"/>
    <origin rpy="-1.570796327 1.0471975511965976 1.8929582768281055" xyz="0.00279 0.03126 -0.11467"/>
    <limit effort="2000" lower="0" upper="1" velocity="1"/>
  </joint>

  <link name="j2n6s300_link_finger_tip_1">
    <contact>
      <lateral_friction value="0.8"/>
      <spinning_friction value="0.1"/>
      <contact_cfm value="0.1"/>
      <contact_erp value="0.2"/>
    </contact>
    <visual>
      <geometry>
        <mesh filename="meshes/finger_distal.dae"/>
      </geometry>
      <material name="finger_gray" />
    </visual>
    <collision>
      <geometry>
        <mesh filename="meshes/finger_distal.dae"/>
      </geometry>
    </collision>
    <inertial>
      <mass value="0.01"/>
      <origin xyz="0.022 0 0"/>
      <inertia ixx="7.8999684e-07" ixy="0" ixz="0" iyy="7.8999684e-07" iyz="0" izz="8e-08"/>
    </inertial>
  </link>

  <joint name="j2n6s300_joint_finger_tip_1" type="fixed">
    <parent link="j2n6s300_link_finger_1"/>
    <child link="j2n6s300_link_finger_tip_1"/>
    <axis xyz="0 0 1"/>
    <origin rpy="0 0 0" xyz="0.044 -0.003 0"/>
    <limit effort="2000" lower="0" upper="2" velocity="1"/>
  </joint>

  <link name="j2n6s300_link_finger_2">
    <contact>
      <lateral_friction value="0.8"/>
      <spinning_friction value="0.1"/>
      <contact_cfm value="0.1"/>
      <contact_erp value="0.2"/>
    </contact>
    <visual>
      <geometry>
        <mesh filename="meshes/finger_proximal.dae"/>
      </geometry>
      <material name="finger_gray" />
    </visual>
    <collision>
      <geometry>
        <mesh filename="meshes/finger_proximal.dae"/>
      </geometry>
    </collision>
    <inertial>
      <mass value="0.01"/>
      <origin xyz="0.022 0 0"/>
      <inertia ixx="7.8999684e-07" ixy="0" ixz="0" iyy="7.8999684e-07" iyz="0" izz="8e-08"/>
    </inertial>
  </link>

  <joint name="j2n6s300_joint_finger_2" type="revolute">
    <parent link="j2n6s300_link_6"/>
    <child link="j2n6s300_link_finger_2"/>
    <axis xyz="0 0 1"/>
    <origin rpy="-1.570796327 1.0471975511965976 -1.2486343767616876" xyz="0.02226 -0.02707 -0.11482"/>
    <limit effort="2000" lower="0" upper="1" velocity="1"/>
  </joint>

  <link name="j2n6s300_link_finger_tip_2">
    <contact>
      <lateral_friction value="0.8"/>
      <spinning_friction value="0.1"/>
      <contact_cfm value="0.1"/>
      <contact_erp value="0.2"/>
    </contact>
    <visual>
      <geometry>
        <mesh filename="meshes/finger_distal.dae"/>
      </geometry>
      <material name="finger_gray" />
    </visual>
    <collision>
      <geometry>
        <mesh filename="meshes/finger_distal.dae"/>
      </geometry>
    </collision>
    <inertial>
      <mass value="0.01"/>
      <origin xyz="0.022 0 0"/>
      <inertia ixx="7.8999684e-07" ixy="0" ixz="0" iyy="7.8999684e-07" iyz="0" izz="8e-08"/>
    </inertial>
  </link>

  <joint name="j2n6s300_joint_finger_tip_2" type="fixed">
    <parent link="j2n6s300_link_finger_2"/>
    <child link="j2n6s300_link_finger_tip_2"/>
    <axis xyz="0 0 1"/>
    <origin rpy="0 0 0" xyz="0.044 -0.003 0"/>
    <limit effort="2000" lower="0" upper="2" velocity="1"/>
  </joint>

  <link name="j2n6s300_link_finger_3">
    <contact>
      <lateral_friction value="0.8"/>
      <spinning_friction value="0.1"/>
      <contact_cfm value="0.1"/>
      <contact_erp value="0.2"/>
    </contact>
    <visual>
      <geometry>
        <mesh filename="meshes/finger_proximal.dae"/>
      </geometry>
      <material name="finger_gray" />
    </visual>
    <collision>
      <geometry>
        <mesh filename="meshes/finger_proximal.dae"/>
      </geometry>
    </collision>
    <inertial>
      <mass value="0.01"/>
      <origin xyz="0.022 0 0"/>
      <inertia ixx="7.8999684e-07" ixy="0" ixz="0" iyy="7.8999684e-07" iyz="0" izz="8e-08"/>
    </inertial>
  </link>

  <joint name="j2n6s300_joint_finger_3" type="revolute">
    <parent link="j2n6s300_link_6"/>
    <child link="j2n6s300_link_finger_3"/>
    <axis xyz="0 0 1"/>
    <origin rpy="-1.570796327 1.0471975511965976 -1.75545216211587" xyz="-0.02226 -0.02707 -0.11482"/>
    <limit effort="2000" lower="0" upper="1" velocity="1"/>
  </joint>

  <link name="j2n6s300_link_finger_tip_3">
    <contact>
      <lateral_friction value="0.8"/>
      <spinning_friction value="0.1"/>
      <contact_cfm value="0.1"/>
      <contact_erp value="0.2"/>
    </contact>
    <visual>
      <geometry>
      <mesh filename="meshes/finger_distal.dae"/>
      </geometry>
      <material name="finger_gray" />
    </visual>
    <collision>
      <geometry>
        <mesh filename="meshes/finger_distal.dae"/>
      </geometry>
    </collision>
    <inertial>
      <mass value="0.01"/>
      <origin xyz="0.022 0 0"/>
      <inertia ixx="7.8999684e-07" ixy="0" ixz="0" iyy="7.8999684e-07" iyz="0" izz="8e-08"/>
    </inertial>
  </link>
  <joint name="j2n6s300_joint_finger_tip_3" type="fixed">
    <parent link="j2n6s300_link_finger_3"/>
    <child link="j2n6s300_link_finger_tip_3"/>
    <axis xyz="0 0 1"/>
    <origin rpy="0 0 0" xyz="0.044 -0.003 0"/>
    <limit effort="2000" lower="0" upper="2" velocity="1"/>
  </joint>
</robot>
